Workbook
Name X_Axis: OFFSET(#REF!,0,0,Page!$C$4,1)

Sheet Page
B2: Investment Settings | G2: Buy & Hold | V2: Rebalanced
B3: Starting Capital ($) | C3: 10000000
B4: Investment Horizon (Years) | C4: 20 | G4: Custom | J4: Traditional (Taxable) | M4: Traditional (PPLI) | P4: Alternatives Enhanced (Taxable) | S4: Alternatives Enhanced (PPLI) | V4: Custom | Y4: Traditional (Taxable) | AB4: Traditional (PPLI) | AE4: Alternatives Enhanced (Taxable) | AH4: Alternatives Enhanced (PPLI)
G5: Projected Value | H5: =Custom!C22 -> 29316021 | J5: =G5 -> Projected Value | K5: ='Trad. Tax.'!C22 -> 26762916 | M5: =G5 -> Projected Value | N5: ='Trad. PPLI'!C22 -> 28437126 | P5: =G5 -> Projected Value | Q5: ='Alts. Tax.'!C22 -> 27153622 | S5: =G5 -> Projected Value | T5: ='Alts. PPLI'!C22 -> 29906035 | V5: Projected Value | W5: =Custom!D22 -> 28633744 | Y5: =V5 -> Projected Value | Z5: ='Trad. Tax.'!D22 -> 25743809 | AB5: =V5 -> Projected Value | AC5: ='Trad. PPLI'!D22 -> 27214746 | AE5: =V5 -> Projected Value | AF5: ='Alts. Tax.'!D22 -> 26313895 | AH5: =V5 -> Projected Value | AI5: ='Alts. PPLI'!D22 -> 28484590
B6: Portfolio Allocation (%) | E6: Allocation Check
B7: Stocks | C7: 0.7 | E7: =IF(SUM(C7:C9)=1,"Good","Must Equal 100%") -> Good | G7: Total Return | J7: =G7 -> Total Return | M7: =J7 -> Total Return | P7: =M7 -> Total Return | S7: =P7 -> Total Return | V7: Total Return | Y7: =V7 -> Total Return | AB7: =Y7 -> Total Return | AE7: =AB7 -> Total Return | AH7: =AE7 -> Total Return
B8: Bonds | C8: 0.2 | G8: Gross | H8: =Custom!C24 -> 3.2594253 | J8: =G8 -> Gross | K8: ='Trad. Tax.'!C24 -> 2.8578934 | M8: =J8 -> Gross | N8: ='Trad. PPLI'!C24 -> 2.8578934 | P8: =M8 -> Gross | Q8: ='Alts. Tax.'!C24 -> 3.0185061 | S8: =P8 -> Gross | T8: ='Alts. PPLI'!C24 -> 3.0185061 | V8: Gross | W8: =Custom!D24 -> 3.1695158 | Y8: =V8 -> Gross | Z8: ='Trad. Tax.'!D24 -> 2.7275635 | AB8: =Y8 -> Gross | AC8: ='Trad. PPLI'!D24 -> 2.7275635 | AE8: =AB8 -> Gross | AF8: ='Alts. Tax.'!D24 -> 2.8987197 | AH8: =AE8 -> Gross | AI8: ='Alts. PPLI'!D24 -> 2.8987197
B9: Alternatives | C9: 0.1 | G9: Net | H9: =Custom!C25 -> 1.9316021 | J9: =G9 -> Net | K9: ='Trad. Tax.'!C25 -> 1.6762916 | M9: =J9 -> Net | N9: ='Trad. PPLI'!C25 -> 1.8437126 | P9: =M9 -> Net | Q9: ='Alts. Tax.'!C25 -> 1.7153622 | S9: =P9 -> Net | T9: ='Alts. PPLI'!C25 -> 1.9906035 | V9: Net | W9: =Custom!D25 -> 1.8633744 | Y9: =V9 -> Net | Z9: ='Trad. Tax.'!D25 -> 1.5743809 | AB9: =Y9 -> Net | AC9: ='Trad. PPLI'!D25 -> 1.7214746 | AE9: =AB9 -> Net | AF9: ='Alts. Tax.'!D25 -> 1.6313895 | AH9: =AE9 -> Net | AI9: ='Alts. PPLI'!D25 -> 1.848459
G10: Drag | H10: =Custom!C26 -> -1.3278232 | J10: =G10 -> Drag | K10: ='Trad. Tax.'!C26 -> -1.1816017 | M10: =J10 -> Drag | N10: ='Trad. PPLI'!C26 -> -1.0141808 | P10: =M10 -> Drag | Q10: ='Alts. Tax.'!C26 -> -1.3031439 | S10: =P10 -> Drag | T10: ='Alts. PPLI'!C26 -> -1.0279026 | V10: Drag | W10: =Custom!D26 -> -1.3061414 | Y10: =V10 -> Drag | Z10: ='Trad. Tax.'!D26 -> -1.1531826 | AB10: =Y10 -> Drag | AC10: ='Trad. PPLI'!D26 -> -1.006089 | AE10: =AB10 -> Drag | AF10: ='Alts. Tax.'!D26 -> -1.2673301 | AH10: =AE10 -> Drag | AI10: ='Alts. PPLI'!D26 -> -1.0502607
B11: Return Assumptions (%)
B12: Stocks | C12: 0.08 | G12: Annualized Return | J12: =G12 -> Annualized Return | M12: =J12 -> Annualized Return | P12: =M12 -> Annualized Return | S12: =P12 -> Annualized Return | V12: Annualized Return | Y12: =V12 -> Annualized Return | AB12: =Y12 -> Annualized Return | AE12: =AB12 -> Annualized Return | AH12: =AE12 -> Annualized Return
B13: Bonds | C13: 0.05 | G13: Gross | H13: =Custom!C28 -> 0.075146264 | J13: =G13 -> Gross | K13: ='Trad. Tax.'!C28 -> 0.069836747 | M13: =J13 -> Gross | N13: ='Trad. PPLI'!C28 -> 0.069836747 | P13: =M13 -> Gross | Q13: ='Alts. Tax.'!C28 -> 0.072020849 | S13: =P13 -> Gross | T13: ='Alts. PPLI'!C28 -> 0.072020849 | V13: Gross | W13: =Custom!D28 -> 0.074 | Y13: =V13 -> Gross | Z13: ='Trad. Tax.'!D28 -> 0.068 | AB13: =Y13 -> Gross | AC13: ='Trad. PPLI'!D28 -> 0.068 | AE13: =AB13 -> Gross | AF13: ='Alts. Tax.'!D28 -> 0.0704 | AH13: =AE13 -> Gross | AI13: ='Alts. PPLI'!D28 -> 0.0704
B14: Alternatives | C14: 0.08 | G14: Net | H14: =Custom!C29 -> 0.055249733 | J14: =G14 -> Net | K14: ='Trad. Tax.'!C29 -> 0.050453112 | M14: =J14 -> Net | N14: ='Trad. PPLI'!C29 -> 0.053644938 | P14: =M14 -> Net | Q14: ='Alts. Tax.'!C29 -> 0.05121461 | S14: =P14 -> Net | T14: ='Alts. PPLI'!C29 -> 0.056301611 | V14: Net | W14: =Custom!D29 -> 0.054008 | Y14: =V14 -> Net | Z14: ='Trad. Tax.'!D29 -> 0.048416 | AB14: =Y14 -> Net | AC14: ='Trad. PPLI'!D29 -> 0.0513328 | AE14: =AB14 -> Net | AF14: ='Alts. Tax.'!D29 -> 0.0495648 | AH14: =AE14 -> Net | AI14: ='Alts. PPLI'!D29 -> 0.0537328
G15: Drag | H15: =Custom!C30 -> -0.019896531 | J15: =G15 -> Drag | K15: ='Trad. Tax.'!C30 -> -0.019383635 | M15: =J15 -> Drag | N15: ='Trad. PPLI'!C30 -> -0.016191809 | P15: =M15 -> Drag | Q15: ='Alts. Tax.'!C30 -> -0.020806239 | S15: =P15 -> Drag | T15: ='Alts. PPLI'!C30 -> -0.015719238 | V15: Drag | W15: =Custom!D30 -> -0.019992 | Y15: =V15 -> Drag | Z15: ='Trad. Tax.'!D30 -> -0.019584 | AB15: =Y15 -> Drag | AC15: ='Trad. PPLI'!D30 -> -0.0166672 | AE15: =AB15 -> Drag | AF15: ='Alts. Tax.'!D30 -> -0.0208352 | AH15: =AE15 -> Drag | AI15: ='Alts. PPLI'!D30 -> -0.0166672
B16: Tax Assumptions (%)
B17: Ordinary Income | C17: 0.37
B18: Capital Gains | C18: 0.2
B19: NIIT | C19: 0.038
B21: PPLI Allocation (%)
B22: Stocks | C22: 0
B23: Bonds | C23: 0
B24: Alternatives | C24: 0
B26: PPLI Costs (%)
B27: Policy Costs | C27: 0.005
B29: Additional Contributions
B30: Year | C30: Amount ($)
M46: Rank | N46: Strategy | P46: Annualized Return (Net) | R46: Projected Value | AB46: Rank | AC46: Strategy | AE46: Annualized Return (Net) | AG46: Projected Value
M49: =Rank!M2 -> 1st | N49: =Rank!I2 -> Alternatives Enhanced (PPLI) | P49: =Rank!K2 -> 0.056301611 | Q49: =_xlfn.CONCAT("+ ",TEXT(P49-$P$61,"0.00%")) -> + 0.58% | R49: =Rank!J2 -> 29906035 | T49: =_xlfn.CONCAT("+ ",TEXT(R49-$R$61,"$#,##0.00")) -> + $3,143,118.93 | AB49: =Rank!M10 -> 1st | AC49: =Rank!I10 -> Custom | AE49: =Rank!K10 -> 0.054008 | AF49: =_xlfn.CONCAT("+ ",TEXT(AE49-$AE$61,"0.00%")) -> + 0.56% | AG49: =Rank!J10 -> 28633744 | AI49: =_xlfn.CONCAT("+ ",TEXT(AG49-$AG$61,"$#,##0.00")) -> + $2,889,935.53
M52: =Rank!M3 -> 2nd | N52: =Rank!I3 -> Custom | P52: =Rank!K3 -> 0.055249733 | Q52: =_xlfn.CONCAT("+ ",TEXT(P52-$P$61,"0.00%")) -> + 0.48% | R52: =Rank!J3 -> 29316021 | T52: =_xlfn.CONCAT("+ ",TEXT(R52-$R$61,"$#,##0.00")) -> + $2,553,104.27 | AB52: =Rank!M11 -> 2nd | AC52: =Rank!I11 -> Alternatives Enhanced (PPLI) | AE52: =Rank!K11 -> 0.0537328 | AF52: =_xlfn.CONCAT("+ ",TEXT(AE52-$AE$61,"0.00%")) -> + 0.53% | AG52: =Rank!J11 -> 28484590 | AI52: =_xlfn.CONCAT("+ ",TEXT(AG52-$AG$61,"$#,##0.00")) -> + $2,740,781.23
M55: =Rank!M4 -> 3rd | N55: =Rank!I4 -> Traditional (PPLI) | P55: =Rank!K4 -> 0.053644938 | Q55: =_xlfn.CONCAT("+ ",TEXT(P55-$P$61,"0.00%")) -> + 0.32% | R55: =Rank!J4 -> 28437126 | T55: =_xlfn.CONCAT("+ ",TEXT(R55-$R$61,"$#,##0.00")) -> + $1,674,209.27 | AB55: =Rank!M12 -> 3rd | AC55: =Rank!I12 -> Traditional (PPLI) | AE55: =Rank!K12 -> 0.0513328 | AF55: =_xlfn.CONCAT("+ ",TEXT(AE55-$AE$61,"0.00%")) -> + 0.29% | AG55: =Rank!J12 -> 27214746 | AI55: =_xlfn.CONCAT("+ ",TEXT(AG55-$AG$61,"$#,##0.00")) -> + $1,470,936.72
M58: =Rank!M5 -> 4th | N58: =Rank!I5 -> Alternatives Enhanced (Taxable) | P58: =Rank!K5 -> 0.05121461 | Q58: =_xlfn.CONCAT("+ ",TEXT(P58-$P$61,"0.00%")) -> + 0.08% | R58: =Rank!J5 -> 27153622 | T58: =_xlfn.CONCAT("+ ",TEXT(R58-$R$61,"$#,##0.00")) -> + $390,705.51 | AB58: =Rank!M13 -> 4th | AC58: =Rank!I13 -> Alternatives Enhanced (Taxable) | AE58: =Rank!K13 -> 0.0495648 | AF58: =_xlfn.CONCAT("+ ",TEXT(AE58-$AE$61,"0.00%")) -> + 0.11% | AG58: =Rank!J13 -> 26313895 | AI58: =_xlfn.CONCAT("+ ",TEXT(AG58-$AG$61,"$#,##0.00")) -> + $570,086.30
M61: =Rank!M6 -> 5th | N61: =Rank!I6 -> Traditional (Taxable) | P61: =Rank!K6 -> 0.050453112 | Q61: =_xlfn.CONCAT("+ ",TEXT(P61-$P$61,"0.00%")) -> + 0.00% | R61: =Rank!J6 -> 26762916 | T61: =_xlfn.CONCAT("+ ",TEXT(R61-$R$61,"$#,##0.00")) -> + $0.00 | AB61: =Rank!M14 -> 5th | AC61: =Rank!I14 -> Traditional (Taxable) | AE61: =Rank!K14 -> 0.048416 | AF61: =_xlfn.CONCAT("+ ",TEXT(AE61-$AE$61,"0.00%")) -> + 0.00% | AG61: =Rank!J14 -> 25743809 | AI61: =_xlfn.CONCAT("+ ",TEXT(AG61-$AG$61,"$#,##0.00")) -> + $0.00

Sheet Chart Feeder >

Sheet WA PIVOT
A1: Buy & Hold | I1: Rebalanced
A6: Row Labels | B6: Custom | C6: Traditional (Taxable) | D6: Traditional (PPLI) | E6: Alternatives Enhanced (Taxable) | F6: Alternatives Enhanced (PPLI) | I6: Row Labels | J6: Custom | K6: Traditional (Taxable) | L6: Traditional (PPLI) | M6: Alternatives Enhanced (Taxable) | N6: Alternatives Enhanced (PPLI)
A7: 1 | B7: 10540080 | C7: 10484160 | D7: 10513328 | E7: 10495648 | F7: 10537328 | I7: 1 | J7: 10540080 | K7: 10484160 | L7: 10513328 | M7: 10495648 | N7: 10537328
A8: 2 | B8: 11109329 | C8: 10991761 | D8: 11053007 | E8: 11015863 | F8: 11103528 | I8: 2 | J8: 11109329 | K8: 10991761 | L8: 11053007 | M8: 11015863 | N8: 11103528
A9: 3 | B9: 11709321 | C9: 11523938 | D9: 11620388 | E9: 11561862 | F9: 11700152 | I9: 3 | J9: 11709321 | K9: 11523938 | L9: 11620388 | M9: 11561862 | N9: 11700152
A10: 4 | B10: 12341718 | C10: 12081881 | D10: 12216895 | E10: 12134923 | F10: 12328834 | I10: 4 | J10: 12341718 | K10: 12081881 | L10: 12216895 | M10: 12134923 | N10: 12328834
A11: 5 | B11: 13008270 | C11: 12666838 | D11: 12844023 | E11: 12736388 | F11: 12991296 | I11: 5 | J11: 13008270 | K11: 12666838 | L11: 12844023 | M11: 12736388 | N11: 12991296
A12: 6 | B12: 13710820 | C12: 13280115 | D12: 13503343 | E12: 13367665 | F12: 13689355 | I12: 6 | J12: 13710820 | K12: 13280115 | L12: 13503343 | M12: 13367665 | N12: 13689355
A13: 7 | B13: 14451314 | C13: 13923085 | D13: 14196507 | E13: 14030230 | F13: 14424923 | I13: 7 | J13: 14451314 | K13: 13923085 | L13: 14196507 | M13: 14030230 | N13: 14424923
A14: 8 | B14: 15231801 | C14: 14597185 | D14: 14925253 | E14: 14725636 | F14: 15200014 | I14: 8 | J14: 15231801 | K14: 14597185 | L14: 14925253 | M14: 14725636 | N14: 15200014
A15: 9 | B15: 16054440 | C15: 15303923 | D15: 15691408 | E15: 15455509 | F15: 16016753 | I15: 9 | J15: 16054440 | K15: 15303923 | L15: 15691408 | M15: 15455509 | N15: 16016753
A16: 10 | B16: 16921508 | C16: 16044877 | D16: 16496892 | E16: 16221558 | F16: 16877378 | I16: 10 | J16: 16921508 | K16: 16044877 | L16: 16496892 | M16: 16221558 | N16: 16877378
A17: 11 | B17: 17835405 | C17: 16821706 | D17: 17343724 | E17: 17025577 | F17: 17784247 | I17: 11 | J17: 17835405 | K17: 16821706 | L17: 17343724 | M17: 17025577 | N17: 17784247
A18: 12 | B18: 18798660 | C18: 17636146 | D18: 18234026 | E18: 17869446 | F18: 18739845 | I18: 12 | J18: 18798660 | K18: 17636146 | L18: 18234026 | M18: 17869446 | N18: 18739845
... A26: 20 | B26: 28633744 | C26: 25743809 | D26: 27214746 | E26: 26313895 | F26: 28484590 | I26: 20 | J26: 28633744 | K26: 25743809 | L26: 27214746 | M26: 26313895 | N26: 28484590
A27: Grand Total | B27: 3.6365197e+08 | C27: 3.4092162e+08 | D27: 3.5257042e+08 | E27: 3.4545666e+08 | F27: 3.6249402e+08 | I27: Grand Total | J27: 3.6365197e+08 | K27: 3.4092162e+08 | L27: 3.5257042e+08 | M27: 3.4545666e+08 | N27: 3.6249402e+08

Sheet WA
A1: =Page!C4 -> 20 | B1: Buy & Hold | K1: =A1 -> 20 | L1: Rebalanced
A5: Year | B5: Custom_ | C5: Traditional (Taxable)_ | D5: Traditional (PPLI)_ | E5: Alternatives Enhanced (Taxable)_ | F5: Alternatives Enhanced (PPLI)_ | K5: Year | L5: Custom_ | M5: Traditional (Taxable)_ | N5: Traditional (PPLI)_ | O5: Alternatives Enhanced (Taxable)_ | P5: Alternatives Enhanced (PPLI)_
A6: {=_xlfn.SEQUENCE(A1,1,1,1)} -> 1 | B6: =IF(A6="","N/A",Custom!V10) -> 10540080 | C6: =IF(A6="","N/A",'Trad. Tax.'!V10) -> 10484160 | D6: =IF(A6="","N/A",'Trad. PPLI'!V10) -> 10513328 | E6: =IF(A6="","N/A",'Alts. Tax.'!V10) -> 10495648 | F6: =IF(A6="","N/A",'Alts. PPLI'!V10) -> 10537328 | K6: {=_xlfn.SEQUENCE(K1,1,1,1)} -> 1 | L6: =IF(K6="","N/A",Custom!X10) -> 10540080 | M6: =IF(K6="","N/A",'Trad. Tax.'!X10) -> 10484160 | N6: =IF(K6="","N/A",'Trad. PPLI'!X10) -> 10513328 | O6: =IF(K6="","N/A",'Alts. Tax.'!X10) -> 10495648 | P6: =IF(K6="","N/A",'Alts. PPLI'!X10) -> 10537328
A7: 2 | B7: =IF(A7="","N/A",Custom!V11) -> 11110858 | C7: =IF(A7="","N/A",'Trad. Tax.'!V11) -> 10994121 | D7: =IF(A7="","N/A",'Trad. PPLI'!V11) -> 11055667 | E7: =IF(A7="","N/A",'Alts. Tax.'!V11) -> 11017804 | F7: =IF(A7="","N/A",'Alts. PPLI'!V11) -> 11106547 | K7: 2 | L7: =IF(K7="","N/A",Custom!X11) -> 11109329 | M7: =IF(K7="","N/A",'Trad. Tax.'!X11) -> 10991761 | N7: =IF(K7="","N/A",'Trad. PPLI'!X11) -> 11053007 | O7: =IF(K7="","N/A",'Alts. Tax.'!X11) -> 11015863 | P7: =IF(K7="","N/A",'Alts. PPLI'!X11) -> 11103528
A8: 3 | B8: =IF(A8="","N/A",Custom!V12) -> 11714132 | C8: =IF(A8="","N/A",'Trad. Tax.'!V12) -> 11531347 | D8: =IF(A8="","N/A",'Trad. PPLI'!V12) -> 11628767 | E8: =IF(A8="","N/A",'Alts. Tax.'!V12) -> 11567955 | F8: =IF(A8="","N/A",'Alts. PPLI'!V12) -> 11709671 | K8: 3 | L8: =IF(K8="","N/A",Custom!X12) -> 11709321 | M8: =IF(K8="","N/A",'Trad. Tax.'!X12) -> 11523938 | N8: =IF(K8="","N/A",'Trad. PPLI'!X12) -> 11620388 | O8: =IF(K8="","N/A",'Alts. Tax.'!X12) -> 11561862 | P8: =IF(K8="","N/A",'Alts. PPLI'!X12) -> 11700152
A9: 4 | B9: =IF(A9="","N/A",Custom!V13) -> 12351804 | C9: =IF(A9="","N/A",'Trad. Tax.'!V13) -> 12097386 | D9: =IF(A9="","N/A",'Trad. PPLI'!V13) -> 12234487 | E9: =IF(A9="","N/A",'Alts. Tax.'!V13) -> 12147677 | F9: =IF(A9="","N/A",'Alts. PPLI'!V13) -> 12348847 | K9: 4 | L9: =IF(K9="","N/A",Custom!X13) -> 12341718 | M9: =IF(K9="","N/A",'Trad. Tax.'!X13) -> 12081881 | N9: =IF(K9="","N/A",'Trad. PPLI'!X13) -> 12216895 | O9: =IF(K9="","N/A",'Alts. Tax.'!X13) -> 12134923 | P9: =IF(K9="","N/A",'Alts. PPLI'!X13) -> 12328834
A10: 5 | B10: =IF(A10="","N/A",Custom!V14) -> 13025890 | C10: =IF(A10="","N/A",'Trad. Tax.'!V14) -> 12693878 | D10: =IF(A10="","N/A",'Trad. PPLI'!V14) -> 12874803 | E10: =IF(A10="","N/A",'Alts. Tax.'!V14) -> 12758633 | F10: =IF(A10="","N/A",'Alts. PPLI'!V14) -> 13026361 | K10: 5 | L10: =IF(K10="","N/A",Custom!X14) -> 13008270 | M10: =IF(K10="","N/A",'Trad. Tax.'!X14) -> 12666838 | N10: =IF(K10="","N/A",'Trad. PPLI'!X14) -> 12844023 | O10: =IF(K10="","N/A",'Alts. Tax.'!X14) -> 12736388 | P10: =IF(K10="","N/A",'Alts. PPLI'!X14) -> 12991296
A11: 6 | B11: =IF(A11="","N/A",Custom!V15) -> 13738528 | C11: =IF(A11="","N/A",'Trad. Tax.'!V15) -> 13322560 | D11: =IF(A11="","N/A",'Trad. PPLI'!V15) -> 13551818 | E11: =IF(A11="","N/A",'Alts. Tax.'!V15) -> 13402585 | F11: =IF(A11="","N/A",'Alts. PPLI'!V15) -> 13744651 | K11: 6 | L11: =IF(K11="","N/A",Custom!X15) -> 13710820 | M11: =IF(K11="","N/A",'Trad. Tax.'!X15) -> 13280115 | N11: =IF(K11="","N/A",'Trad. PPLI'!X15) -> 13503343 | O11: =IF(K11="","N/A",'Alts. Tax.'!X15) -> 13367665 | P11: =IF(K11="","N/A",'Alts. PPLI'!X15) -> 13689355
A12: 7 | B12: =IF(A12="","N/A",Custom!V16) -> 14491980 | C12: =IF(A12="","N/A",'Trad. Tax.'!V16) -> 13985270 | D12: =IF(A12="","N/A",'Trad. PPLI'!V16) -> 14267764 | E12: =IF(A12="","N/A",'Alts. Tax.'!V16) -> 14081397 | F12: =IF(A12="","N/A",'Alts. PPLI'!V16) -> 14506314 | K12: 7 | L12: =IF(K12="","N/A",Custom!X16) -> 14451314 | M12: =IF(K12="","N/A",'Trad. Tax.'!X16) -> 13923085 | N12: =IF(K12="","N/A",'Trad. PPLI'!X16) -> 14196507 | O12: =IF(K12="","N/A",'Alts. Tax.'!X16) -> 14030230 | P12: =IF(K12="","N/A",'Alts. PPLI'!X16) -> 14424923
A13: 8 | B13: =IF(A13="","N/A",Custom!V17) -> 15288646 | C13: =IF(A13="","N/A",'Trad. Tax.'!V17) -> 14683955 | D13: =IF(A13="","N/A",'Trad. PPLI'!V17) -> 15025018 | E13: =IF(A13="","N/A",'Alts. Tax.'!V17) -> 14797041 | F13: =IF(A13="","N/A",'Alts. PPLI'!V17) -> 15314120 | K13: 8 | L13: =IF(K13="","N/A",Custom!X17) -> 15231801 | M13: =IF(K13="","N/A",'Trad. Tax.'!X17) -> 14597185 | N13: =IF(K13="","N/A",'Trad. PPLI'!X17) -> 14925253 | O13: =IF(K13="","N/A",'Alts. Tax.'!X17) -> 14725636 | P13: =IF(K13="","N/A",'Alts. PPLI'!X17) -> 15200014
A14: 9 | B14: =IF(A14="","N/A",Custom!V18) -> 16131067 | C14: =IF(A14="","N/A",'Trad. Tax.'!V18) -> 15420678 | D14: =IF(A14="","N/A",'Trad. PPLI'!V18) -> 15826105 | E14: =IF(A14="","N/A",'Alts. Tax.'!V18) -> 15551601 | F14: =IF(A14="","N/A",'Alts. PPLI'!V18) -> 16171020 | K14: 9 | L14: =IF(K14="","N/A",Custom!X18) -> 16054440 | M14: =IF(K14="","N/A",'Trad. Tax.'!X18) -> 15303923 | N14: =IF(K14="","N/A",'Trad. PPLI'!X18) -> 15691408 | O14: =IF(K14="","N/A",'Alts. Tax.'!X18) -> 15455509 | P14: =IF(K14="","N/A",'Alts. PPLI'!X18) -> 16016753
A15: 10 | B15: =IF(A15="","N/A",Custom!V19) -> 17021936 | C15: =IF(A15="","N/A",'Trad. Tax.'!V19) -> 16197623 | D15: =IF(A15="","N/A",'Trad. PPLI'!V19) -> 16673712 | E15: =IF(A15="","N/A",'Alts. Tax.'!V19) -> 16347284 | F15: =IF(A15="","N/A",'Alts. PPLI'!V19) -> 17080162 | K15: 10 | L15: =IF(K15="","N/A",Custom!X19) -> 16921508 | M15: =IF(K15="","N/A",'Trad. Tax.'!X19) -> 16044877 | N15: =IF(K15="","N/A",'Trad. PPLI'!X19) -> 16496892 | O15: =IF(K15="","N/A",'Alts. Tax.'!X19) -> 16221558 | P15: =IF(K15="","N/A",'Alts. PPLI'!X19) -> 16877378
A16: 11 | B16: =IF(A16="","N/A",Custom!V20) -> 17964107 | C16: =IF(A16="","N/A",'Trad. Tax.'!V20) -> 17017103 | D16: =IF(A16="","N/A",'Trad. PPLI'!V20) -> 17570696 | E16: =IF(A16="","N/A",'Alts. Tax.'!V20) -> 17186426 | F16: =IF(A16="","N/A",'Alts. PPLI'!V20) -> 18044900 | K16: 11 | L16: =IF(K16="","N/A",Custom!X20) -> 17835405 | M16: =IF(K16="","N/A",'Trad. Tax.'!X20) -> 16821706 | N16: =IF(K16="","N/A",'Trad. PPLI'!X20) -> 17343724 | O16: =IF(K16="","N/A",'Alts. Tax.'!X20) -> 17025577 | P16: =IF(K16="","N/A",'Alts. PPLI'!X20) -> 17784247
A17: 12 | B17: =IF(A17="","N/A",Custom!V21) -> 18960602 | C17: =IF(A17="","N/A",'Trad. Tax.'!V21) -> 17881568 | D17: =IF(A17="","N/A",'Trad. PPLI'!V21) -> 18520095 | E17: =IF(A17="","N/A",'Alts. Tax.'!V21) -> 18071498 | F17: =IF(A17="","N/A",'Alts. PPLI'!V21) -> 19068813 | K17: 12 | L17: =IF(K17="","N/A",Custom!X21) -> 18798660 | M17: =IF(K17="","N/A",'Trad. Tax.'!X21) -> 17636146 | N17: =IF(K17="","N/A",'Trad. PPLI'!X21) -> 18234026 | O17: =IF(K17="","N/A",'Alts. Tax.'!X21) -> 17869446 | P17: =IF(K17="","N/A",'Alts. PPLI'!X21) -> 18739845
A18: 13 | B18: =IF(A18="","N/A",Custom!V22) -> 20014627 | C18: =IF(A18="","N/A",'Trad. Tax.'!V22) -> 18793612 | D18: =IF(A18="","N/A",'Trad. PPLI'!V22) -> 19525142 | E18: =IF(A18="","N/A",'Alts. Tax.'!V22) -> 19005113 | F18: =IF(A18="","N/A",'Alts. PPLI'!V22) -> 20155716 | K18: 13 | L18: =IF(K18="","N/A",Custom!X22) -> 19813938 | M18: =IF(K18="","N/A",'Trad. Tax.'!X22) -> 18490017 | N18: =IF(K18="","N/A",'Trad. PPLI'!X22) -> 19170030 | O18: =IF(K18="","N/A",'Alts. Tax.'!X22) -> 18755141 | P18: =IF(K18="","N/A",'Alts. PPLI'!X22) -> 19746789
... A25: 20 | B25: =IF(A25="","N/A",Custom!V29) -> 29316021 | C25: =IF(A25="","N/A",'Trad. Tax.'!V29) -> 26762916 | D25: =IF(A25="","N/A",'Trad. PPLI'!V29) -> 28437126 | E25: =IF(A25="","N/A",'Alts. Tax.'!V29) -> 27153622 | F25: =IF(A25="","N/A",'Alts. PPLI'!V29) -> 29906035 | K25: 20 | L25: =IF(K25="","N/A",Custom!X29) -> 28633744 | M25: =IF(K25="","N/A",'Trad. Tax.'!X29) -> 25743809 | N25: =IF(K25="","N/A",'Trad. PPLI'!X29) -> 27214746 | O25: =IF(K25="","N/A",'Alts. Tax.'!X29) -> 26313895 | P25: =IF(K25="","N/A",'Alts. PPLI'!X29) -> 28484590
B26: =IF(A26="","N/A",Custom!V30) -> N/A | C26: =IF(A26="","N/A",'Trad. Tax.'!V30) -> N/A | D26: =IF(A26="","N/A",'Trad. PPLI'!V30) -> N/A | E26: =IF(A26="","N/A",'Alts. Tax.'!V30) -> N/A | F26: =IF(A26="","N/A",'Alts. PPLI'!V30) -> N/A | L26: =IF(K26="","N/A",Custom!X30) -> N/A | M26: =IF(K26="","N/A",'Trad. Tax.'!X30) -> N/A | N26: =IF(K26="","N/A",'Trad. PPLI'!X30) -> N/A | O26: =IF(K26="","N/A",'Alts. Tax.'!X30) -> N/A | P26: =IF(K26="","N/A",'Alts. PPLI'!X30) -> N/A
B27: =IF(A27="","N/A",Custom!V31) -> N/A | C27: =IF(A27="","N/A",'Trad. Tax.'!V31) -> N/A | D27: =IF(A27="","N/A",'Trad. PPLI'!V31) -> N/A | E27: =IF(A27="","N/A",'Alts. Tax.'!V31) -> N/A | F27: =IF(A27="","N/A",'Alts. PPLI'!V31) -> N/A | L27: =IF(K27="","N/A",Custom!X31) -> N/A | M27: =IF(K27="","N/A",'Trad. Tax.'!X31) -> N/A | N27: =IF(K27="","N/A",'Trad. PPLI'!X31) -> N/A | O27: =IF(K27="","N/A",'Alts. Tax.'!X31) -> N/A | P27: =IF(K27="","N/A",'Alts. PPLI'!X31) -> N/A
B28: =IF(A28="","N/A",Custom!V32) -> N/A | C28: =IF(A28="","N/A",'Trad. Tax.'!V32) -> N/A | D28: =IF(A28="","N/A",'Trad. PPLI'!V32) -> N/A | E28: =IF(A28="","N/A",'Alts. Tax.'!V32) -> N/A | F28: =IF(A28="","N/A",'Alts. PPLI'!V32) -> N/A | L28: =IF(K28="","N/A",Custom!X32) -> N/A | M28: =IF(K28="","N/A",'Trad. Tax.'!X32) -> N/A | N28: =IF(K28="","N/A",'Trad. PPLI'!X32) -> N/A | O28: =IF(K28="","N/A",'Alts. Tax.'!X32) -> N/A | P28: =IF(K28="","N/A",'Alts. PPLI'!X32) -> N/A
B29: =IF(A29="","N/A",Custom!V33) -> N/A | C29: =IF(A29="","N/A",'Trad. Tax.'!V33) -> N/A | D29: =IF(A29="","N/A",'Trad. PPLI'!V33) -> N/A | E29: =IF(A29="","N/A",'Alts. Tax.'!V33) -> N/A | F29: =IF(A29="","N/A",'Alts. PPLI'!V33) -> N/A | L29: =IF(K29="","N/A",Custom!X33) -> N/A | M29: =IF(K29="","N/A",'Trad. Tax.'!X33) -> N/A | N29: =IF(K29="","N/A",'Trad. PPLI'!X33) -> N/A | O29: =IF(K29="","N/A",'Alts. Tax.'!X33) -> N/A | P29: =IF(K29="","N/A",'Alts. PPLI'!X33) -> N/A
B30: =IF(A30="","N/A",Custom!V34) -> N/A | C30: =IF(A30="","N/A",'Trad. Tax.'!V34) -> N/A | D30: =IF(A30="","N/A",'Trad. PPLI'!V34) -> N/A | E30: =IF(A30="","N/A",'Alts. Tax.'!V34) -> N/A | F30: =IF(A30="","N/A",'Alts. PPLI'!V34) -> N/A | L30: =IF(K30="","N/A",Custom!X34) -> N/A | M30: =IF(K30="","N/A",'Trad. Tax.'!X34) -> N/A | N30: =IF(K30="","N/A",'Trad. PPLI'!X34) -> N/A | O30: =IF(K30="","N/A",'Alts. Tax.'!X34) -> N/A | P30: =IF(K30="","N/A",'Alts. PPLI'!X34) -> N/A
B31: =IF(A31="","N/A",Custom!V35) -> N/A | C31: =IF(A31="","N/A",'Trad. Tax.'!V35) -> N/A | D31: =IF(A31="","N/A",'Trad. PPLI'!V35) -> N/A | E31: =IF(A31="","N/A",'Alts. Tax.'!V35) -> N/A | F31: =IF(A31="","N/A",'Alts. PPLI'!V35) -> N/A | L31: =IF(K31="","N/A",Custom!X35) -> N/A | M31: =IF(K31="","N/A",'Trad. Tax.'!X35) -> N/A | N31: =IF(K31="","N/A",'Trad. PPLI'!X35) -> N/A | O31: =IF(K31="","N/A",'Alts. Tax.'!X35) -> N/A | P31: =IF(K31="","N/A",'Alts. PPLI'!X35) -> N/A
B32: =IF(A32="","N/A",Custom!V36) -> N/A | C32: =IF(A32="","N/A",'Trad. Tax.'!V36) -> N/A | D32: =IF(A32="","N/A",'Trad. PPLI'!V36) -> N/A | E32: =IF(A32="","N/A",'Alts. Tax.'!V36) -> N/A | F32: =IF(A32="","N/A",'Alts. PPLI'!V36) -> N/A | L32: =IF(K32="","N/A",Custom!X36) -> N/A | M32: =IF(K32="","N/A",'Trad. Tax.'!X36) -> N/A | N32: =IF(K32="","N/A",'Trad. PPLI'!X36) -> N/A | O32: =IF(K32="","N/A",'Alts. Tax.'!X36) -> N/A | P32: =IF(K32="","N/A",'Alts. PPLI'!X36) -> N/A
B33: =IF(A33="","N/A",Custom!V37) -> N/A | C33: =IF(A33="","N/A",'Trad. Tax.'!V37) -> N/A | D33: =IF(A33="","N/A",'Trad. PPLI'!V37) -> N/A | E33: =IF(A33="","N/A",'Alts. Tax.'!V37) -> N/A | F33: =IF(A33="","N/A",'Alts. PPLI'!V37) -> N/A | L33: =IF(K33="","N/A",Custom!X37) -> N/A | M33: =IF(K33="","N/A",'Trad. Tax.'!X37) -> N/A | N33: =IF(K33="","N/A",'Trad. PPLI'!X37) -> N/A | O33: =IF(K33="","N/A",'Alts. Tax.'!X37) -> N/A | P33: =IF(K33="","N/A",'Alts. PPLI'!X37) -> N/A
B34: =IF(A34="","N/A",Custom!V38) -> N/A | C34: =IF(A34="","N/A",'Trad. Tax.'!V38) -> N/A | D34: =IF(A34="","N/A",'Trad. PPLI'!V38) -> N/A | E34: =IF(A34="","N/A",'Alts. Tax.'!V38) -> N/A | F34: =IF(A34="","N/A",'Alts. PPLI'!V38) -> N/A | L34: =IF(K34="","N/A",Custom!X38) -> N/A | M34: =IF(K34="","N/A",'Trad. Tax.'!X38) -> N/A | N34: =IF(K34="","N/A",'Trad. PPLI'!X38) -> N/A | O34: =IF(K34="","N/A",'Alts. Tax.'!X38) -> N/A | P34: =IF(K34="","N/A",'Alts. PPLI'!X38) -> N/A
B35: =IF(A35="","N/A",Custom!V39) -> N/A | C35: =IF(A35="","N/A",'Trad. Tax.'!V39) -> N/A | D35: =IF(A35="","N/A",'Trad. PPLI'!V39) -> N/A | E35: =IF(A35="","N/A",'Alts. Tax.'!V39) -> N/A | F35: =IF(A35="","N/A",'Alts. PPLI'!V39) -> N/A | L35: =IF(K35="","N/A",Custom!X39) -> N/A | M35: =IF(K35="","N/A",'Trad. Tax.'!X39) -> N/A | N35: =IF(K35="","N/A",'Trad. PPLI'!X39) -> N/A | O35: =IF(K35="","N/A",'Alts. Tax.'!X39) -> N/A | P35: =IF(K35="","N/A",'Alts. PPLI'!X39) -> N/A
B36: =IF(A36="","N/A",Custom!V40) -> N/A | C36: =IF(A36="","N/A",'Trad. Tax.'!V40) -> N/A | D36: =IF(A36="","N/A",'Trad. PPLI'!V40) -> N/A | E36: =IF(A36="","N/A",'Alts. Tax.'!V40) -> N/A | F36: =IF(A36="","N/A",'Alts. PPLI'!V40) -> N/A | L36: =IF(K36="","N/A",Custom!X40) -> N/A | M36: =IF(K36="","N/A",'Trad. Tax.'!X40) -> N/A | N36: =IF(K36="","N/A",'Trad. PPLI'!X40) -> N/A | O36: =IF(K36="","N/A",'Alts. Tax.'!X40) -> N/A | P36: =IF(K36="","N/A",'Alts. PPLI'!X40) -> N/A
B37: =IF(A37="","N/A",Custom!V41) -> N/A | C37: =IF(A37="","N/A",'Trad. Tax.'!V41) -> N/A | D37: =IF(A37="","N/A",'Trad. PPLI'!V41) -> N/A | E37: =IF(A37="","N/A",'Alts. Tax.'!V41) -> N/A | F37: =IF(A37="","N/A",'Alts. PPLI'!V41) -> N/A | L37: =IF(K37="","N/A",Custom!X41) -> N/A | M37: =IF(K37="","N/A",'Trad. Tax.'!X41) -> N/A | N37: =IF(K37="","N/A",'Trad. PPLI'!X41) -> N/A | O37: =IF(K37="","N/A",'Alts. Tax.'!X41) -> N/A | P37: =IF(K37="","N/A",'Alts. PPLI'!X41) -> N/A
... B105: =IF(A105="","N/A",Custom!V109) -> N/A | C105: =IF(A105="","N/A",'Trad. Tax.'!V109) -> N/A | D105: =IF(A105="","N/A",'Trad. PPLI'!V109) -> N/A | E105: =IF(A105="","N/A",'Alts. Tax.'!V109) -> N/A | F105: =IF(A105="","N/A",'Alts. PPLI'!V109) -> N/A | L105: =IF(K105="","N/A",Custom!X109) -> N/A | M105: =IF(K105="","N/A",'Trad. Tax.'!X109) -> N/A | N105: =IF(K105="","N/A",'Trad. PPLI'!X109) -> N/A | O105: =IF(K105="","N/A",'Alts. Tax.'!X109) -> N/A | P105: =IF(K105="","N/A",'Alts. PPLI'!X109) -> N/A

Sheet Rank
A1: Buy & Hold
A2: =Page!C4 -> 20 | C2: Custom | D2: =Page!H5 -> 29316021 | E2: =Page!H14 -> 0.055249733 | F2: =_xlfn.RANK.EQ(D2,$D$2:$D$6,0) -> 2 | G2: =_xlfn.XLOOKUP(F2,$O$2:$O$6,$P$2:$P$6) -> 2nd | I2: {=_xlfn._xlws.SORT(C2:G6,2,-1)} -> Alternatives Enhanced (PPLI) | J2: 29906035 | K2: 0.056301611 | L2: 1 | M2: 1st | O2: 1 | P2: 1st
C3: Traditional (Taxable) | D3: =Page!K5 -> 26762916 | E3: =Page!K14 -> 0.050453112 | F3: =_xlfn.RANK.EQ(D3,$D$2:$D$6,0) -> 5 | G3: =_xlfn.XLOOKUP(F3,$O$2:$O$6,$P$2:$P$6) -> 5th | I3: Custom | J3: 29316021 | K3: 0.055249733 | L3: 2 | M3: 2nd | O3: 2 | P3: 2nd
C4: Traditional (PPLI) | D4: =Page!N5 -> 28437126 | E4: =Page!N14 -> 0.053644938 | F4: =_xlfn.RANK.EQ(D4,$D$2:$D$6,0) -> 3 | G4: =_xlfn.XLOOKUP(F4,$O$2:$O$6,$P$2:$P$6) -> 3rd | I4: Traditional (PPLI) | J4: 28437126 | K4: 0.053644938 | L4: 3 | M4: 3rd | O4: 3 | P4: 3rd
C5: Alternatives Enhanced (Taxable) | D5: =Page!Q5 -> 27153622 | E5: =Page!Q14 -> 0.05121461 | F5: =_xlfn.RANK.EQ(D5,$D$2:$D$6,0) -> 4 | G5: =_xlfn.XLOOKUP(F5,$O$2:$O$6,$P$2:$P$6) -> 4th | I5: Alternatives Enhanced (Taxable) | J5: 27153622 | K5: 0.05121461 | L5: 4 | M5: 4th | O5: 4 | P5: 4th
C6: Alternatives Enhanced (PPLI) | D6: =Page!T5 -> 29906035 | E6: =Page!T14 -> 0.056301611 | F6: =_xlfn.RANK.EQ(D6,$D$2:$D$6,0) -> 1 | G6: =_xlfn.XLOOKUP(F6,$O$2:$O$6,$P$2:$P$6) -> 1st | I6: Traditional (Taxable) | J6: 26762916 | K6: 0.050453112 | L6: 5 | M6: 5th | O6: 5 | P6: 5th
A9: Rebalanced
A10: =A2 -> 20 | C10: Custom | D10: =Page!W5 -> 28633744 | E10: =Page!W14 -> 0.054008 | F10: =_xlfn.RANK.EQ(D10,$D$10:$D$14,0) -> 1 | G10: =_xlfn.XLOOKUP(F10,$O$2:$O$6,$P$2:$P$6) -> 1st | I10: {=_xlfn._xlws.SORT(C10:G14,2,-1)} -> Custom | J10: 28633744 | K10: 0.054008 | L10: 1 | M10: 1st | O10: 1 | P10: 1st
C11: Traditional (Taxable) | D11: =Page!Z5 -> 25743809 | E11: =Page!Z14 -> 0.048416 | F11: =_xlfn.RANK.EQ(D11,$D$10:$D$14,0) -> 5 | G11: =_xlfn.XLOOKUP(F11,$O$2:$O$6,$P$2:$P$6) -> 5th | I11: Alternatives Enhanced (PPLI) | J11: 28484590 | K11: 0.0537328 | L11: 2 | M11: 2nd | O11: 2 | P11: 2nd
C12: Traditional (PPLI) | D12: =Page!AC5 -> 27214746 | E12: =Page!AC14 -> 0.0513328 | F12: =_xlfn.RANK.EQ(D12,$D$10:$D$14,0) -> 3 | G12: =_xlfn.XLOOKUP(F12,$O$2:$O$6,$P$2:$P$6) -> 3rd | I12: Traditional (PPLI) | J12: 27214746 | K12: 0.0513328 | L12: 3 | M12: 3rd | O12: 3 | P12: 3rd
C13: Alternatives Enhanced (Taxable) | D13: =Page!AF5 -> 26313895 | E13: =Page!AF14 -> 0.0495648 | F13: =_xlfn.RANK.EQ(D13,$D$10:$D$14,0) -> 4 | G13: =_xlfn.XLOOKUP(F13,$O$2:$O$6,$P$2:$P$6) -> 4th | I13: Alternatives Enhanced (Taxable) | J13: 26313895 | K13: 0.0495648 | L13: 4 | M13: 4th | O13: 4 | P13: 4th
C14: Alternatives Enhanced (PPLI) | D14: =Page!AI5 -> 28484590 | E14: =Page!AI14 -> 0.0537328 | F14: =_xlfn.RANK.EQ(D14,$D$10:$D$14,0) -> 2 | G14: =_xlfn.XLOOKUP(F14,$O$2:$O$6,$P$2:$P$6) -> 2nd | I14: Traditional (Taxable) | J14: 25743809 | K14: 0.048416 | L14: 5 | M14: 5th | O14: 5 | P14: 5th

Sheet Strategy Feeder >

Sheet Custom
B2: Initial Capital ($) | C2: =Page!C3 -> 10000000 | I2: Stocks (Taxable) | J2: Stocks (Taxable) | K2: Stocks (PPLI) | L2: Stocks (PPLI) | M2: Bonds (Taxable) | N2: Bonds (Taxable) | O2: Bonds (PPLI) | P2: Bonds (PPLI) | Q2: Alternatives (Taxable) | R2: Alternatives (Taxable) | S2: Alternatives (PPLI) | T2: Alternatives (PPLI) | W2: Weighted Average | X2: Weighted Average
B3: Time Horizon (Years) | C3: =Page!C4 -> 20 | H3: Weight | I3: =$D$7*(1-$E$7) -> 0.7 | J3: =$D$7*(1-$E$7) -> 0.7 | K3: =$D$7*$E$7 -> 0 | L3: =$D$7*$E$7 -> 0 | M3: =$D$8*(1-$E$8) -> 0.2 | N3: =$D$8*(1-$E$8) -> 0.2 | O3: =$D$8*$E$8 -> 0 | P3: =$D$8*$E$8 -> 0 | Q3: =$D$9*(1-$E$9) -> 0.1 | R3: =$D$9*(1-$E$9) -> 0.1 | S3: =$D$9*$E$9 -> 0 | T3: =$D$9*$E$9 -> 0 | W3: =SUM(I3,K3,M3,O3,Q3,S3) -> 1 | X3: =SUM(J3,L3,N3,P3,R3,T3) -> 1
H4: Return | I4: =$C$7 -> 0.08 | J4: =$C$7 -> 0.08 | K4: =$C$7 -> 0.08 | L4: =$C$7 -> 0.08 | M4: =$C$8 -> 0.05 | N4: =$C$8 -> 0.05 | O4: =$C$8 -> 0.05 | P4: =$C$8 -> 0.05 | Q4: =$C$9 -> 0.08 | R4: =$C$9 -> 0.08 | S4: =$C$9 -> 0.08 | T4: =$C$9 -> 0.08 | W4: =SUMPRODUCT(I3:T3,I4:T4)/2 -> 0.074 | X4: =SUMPRODUCT(I3:T3,I4:T4)/2 -> 0.074
D5: =IF(SUM(D7:D9)<>1,"Error","Good") -> Good | H5: Drag | I5: 0 | J5: =$C$7*($C$15+$C$16) -> 0.01904 | K5: 0 | L5: =$C$11 -> 0.005 | M5: 0 | N5: =$C$8*($C$14+$C$16) -> 0.0204 | O5: 0 | P5: =$C$11 -> 0.005 | Q5: 0 | R5: =(50%*$C$9*($C$14+$C$16))+(50%*$C$9*($C$15+$C$16)) -> 0.02584 | S5: 0 | T5: =$C$11 -> 0.005 | W5: 0 | X5: =SUMPRODUCT(J3:T3,J5:T5) -> 0.019992
C6: Returns | D6: Weight | E6: PPLI Allocation
B7: Stocks | C7: =Page!C12 -> 0.08 | D7: =Page!C7 -> 0.7 | E7: =Page!C22 -> 0 | U7: Buy & Hold | V7: Buy & Hold | W7: Rebalanced | X7: Rebalanced | Y7: Buy & Hold | Z7: Buy & Hold | AA7: Buy & Hold | AB7: Rebalanced | AC7: Rebalanced | AD7: Rebalanced | AE7: Buy & Hold | AF7: Buy & Hold | AG7: Buy & Hold | AH7: Rebalanced | AI7: Rebalanced | AJ7: Rebalanced | AK7: Buy & Hold | AL7: Buy & Hold | AM7: Buy & Hold | AN7: Rebalanced | AO7: Rebalanced | AP7: Rebalanced
B8: Bonds | C8: =Page!C13 -> 0.05 | D8: =Page!C8 -> 0.2 | E8: =Page!C23 -> 0 | I8: Gross | J8: Net | K8: Gross | L8: Net | M8: Gross | N8: Net | O8: Gross | P8: Net | Q8: Gross | R8: Net | S8: Gross | T8: Net | U8: Gross | V8: Net | W8: Gross | X8: Net | Y8: Gross | Z8: Net | AB8: Gross | AC8: Net | AE8: Gross | AF8: Net | AH8: Gross | AI8: Net | AK8: Gross | AL8: Net | AN8: Gross | AO8: Net
B9: Alternatives | C9: =Page!C14 -> 0.08 | D9: =Page!C9 -> 0.1 | E9: =Page!C24 -> 0 | G9: Year | H9: Contributions | I9: Stocks (Taxable) | J9: Stocks (Taxable) | K9: Stocks (PPLI) | L9: Stocks (PPLI) | M9: Bonds (Taxable) | N9: Bonds (Taxable) | O9: Bonds (PPLI) | P9: Bonds (PPLI) | Q9: Alternatives (Taxable) | R9: Alternatives (Taxable) | S9: Alternatives (PPLI) | T9: Alternatives (PPLI) | U9: Total | V9: Total | W9: Total | X9: Total | Y9: Period Return | Z9: Period Return | AA9: Period Drag | AB9: Period Return | AC9: Period Return | AD9: Period Drag | AE9: Total Return | AF9: Total Return | AG9: Total Drag | AH9: Total Return | AI9: Total Return | AJ9: Total Drag | AK9: Total Return (Annualized) | AL9: Total Return (Annualized) | AM9: Annaulized Drag | AN9: Total Return (Annualized) | AO9: Total Return (Annualized) | AP9: Annaulized Drag
G10: {=_xlfn.SEQUENCE(C3,1,1,1)} -> 1 | H10: =IF(G10="","",SUMIFS(Add_Contributions[[#All],[Amount ($)]],Add_Contributions[[#All],[Year]],G10)) -> 0 | I10: =IF($G10="","",IF($G10=1,(($C$2+$H10)*I$3)*(1+(I$4-I$5)),((I9+($H10*I$3))*(1+(I$4-I$5))))) -> 7560000 | J10: =IF($G10="","",IF($G10=1,(($C$2+$H10)*J$3)*(1+(J$4-J$5)),((J9+($H10*J$3))*(1+(J$4-J$5))))) -> 7426720 | K10: =IF($G10="","",IF($G10=1,(($C$2+$H10)*K$3)*(1+(K$4-K$5)),((K9+($H10*K$3))*(1+(K$4-K$5))))) -> 0 | L10: =IF($G10="","",IF($G10=1,(($C$2+$H10)*L$3)*(1+(L$4-L$5)),((L9+($H10*L$3))*(1+(L$4-L$5))))) -> 0 | M10: =IF($G10="","",IF($G10=1,(($C$2+$H10)*M$3)*(1+(M$4-M$5)),((M9+($H10*M$3))*(1+(M$4-M$5))))) -> 2100000 | N10: =IF($G10="","",IF($G10=1,(($C$2+$H10)*N$3)*(1+(N$4-N$5)),((N9+($H10*N$3))*(1+(N$4-N$5))))) -> 2059200 | O10: =IF($G10="","",IF($G10=1,(($C$2+$H10)*O$3)*(1+(O$4-O$5)),((O9+($H10*O$3))*(1+(O$4-O$5))))) -> 0 | P10: =IF($G10="","",IF($G10=1,(($C$2+$H10)*P$3)*(1+(P$4-P$5)),((P9+($H10*P$3))*(1+(P$4-P$5))))) -> 0 | ... T10: =IF($G10="","",IF($G10=1,(($C$2+$H10)*T$3)*(1+(T$4-T$5)),((T9+($H10*T$3))*(1+(T$4-T$5))))) -> 0 | U10: =IF(G10="","",SUM(I10,K10,M10,O10,Q10,S10)) -> 10740000 | V10: =IF(H10="","",SUM(J10,L10,N10,P10,R10,T10)) -> 10540080 | W10: =IF($G10="","",IF($G10=1,(($C$2+$H10)*W$3)*(1+(W$4-W$5)),((W9+($H10*W$3))*(1+(W$4-W$5))))) -> 10740000 | X10: =IF($G10="","",IF($G10=1,(($C$2+$H10)*X$3)*(1+(X$4-X$5)),((X9+($H10*X$3))*(1+(X$4-X$5))))) -> 10540080 | Y10: =IF($G10="","",IF($G10=1,(U10-$C$2-H10)/($C$2+H10),(U10-U9-H10)/(U9+H10))) -> 0.074 | Z10: =IF($G10="","",IF($G10=1,(V10-$C$2-H10)/($C$2+H10),(V10-V9-H10)/(V9+H10))) -> 0.054008 | AA10: =IF($G10="","",Z10-Y10) -> -0.019992 | AB10: =IF($G10="","",IF($G10=1,(W10-$C$2-H10)/($C$2+H10),(W10-W9-H10)/(W9+H10))) -> 0.074 | AC10: =IF($G10="","",IF($G10=1,(X10-$C$2-H10)/($C$2+H10),(X10-X9-H10)/(X9+H10))) -> 0.054008 | AD10: =IF($G10="","",AC10-AB10) -> -0.019992 | AE10: =IF($G10="","",IF($G10=1,Y10,(1+Y10)*(1+AE9)-1)) -> 0.074 | AF10: =IF($G10="","",IF($G10=1,Z10,(1+Z10)*(1+AF9)-1)) -> 0.054008 | AG10: =IF($G10="","",AF10-AE10) -> -0.019992 | AH10: =IF($G10="","",IF($G10=1,AB10,(1+AB10)*(1+AH9)-1)) -> 0.074 | AI10: =IF($G10="","",IF($G10=1,AC10,(1+AC10)*(1+AI9)-1)) -> 0.054008 | AJ10: =IF($G10="","",AI10-AH10) -> -0.019992 | AK10: =IF($G10="","",(1+AE10)^(1/G10)-1) -> 0.074 | AL10: =IF($G10="","",(1+AF10)^(1/G10)-1) -> 0.054008 | AM10: =IF($G10="","",AL10-AK10) -> -0.019992 | AN10: =IF($G10="","",(1+AH10)^(1/G10)-1) -> 0.074 | AO10: =IF($G10="","",(1+AI10)^(1/G10)-1) -> 0.054008 | AP10: =IF($G10="","",AO10-AN10) -> -0.019992
B11: PPLI Policy Costs | C11: =Page!C27 -> 0.005 | G11: 2 | H11: =IF(G11="","",SUMIFS(Add_Contributions[[#All],[Amount ($)]],Add_Contributions[[#All],[Year]],G11)) -> 0 | I11: =IF($G11="","",IF($G11=1,(($C$2+$H11)*I$3)*(1+(I$4-I$5)),((I10+($H11*I$3))*(1+(I$4-I$5))))) -> 8164800 | J11: =IF($G11="","",IF($G11=1,(($C$2+$H11)*J$3)*(1+(J$4-J$5)),((J10+($H11*J$3))*(1+(J$4-J$5))))) -> 7879452.9 | K11: =IF($G11="","",IF($G11=1,(($C$2+$H11)*K$3)*(1+(K$4-K$5)),((K10+($H11*K$3))*(1+(K$4-K$5))))) -> 0 | L11: =IF($G11="","",IF($G11=1,(($C$2+$H11)*L$3)*(1+(L$4-L$5)),((L10+($H11*L$3))*(1+(L$4-L$5))))) -> 0 | M11: =IF($G11="","",IF($G11=1,(($C$2+$H11)*M$3)*(1+(M$4-M$5)),((M10+($H11*M$3))*(1+(M$4-M$5))))) -> 2205000 | N11: =IF($G11="","",IF($G11=1,(($C$2+$H11)*N$3)*(1+(N$4-N$5)),((N10+($H11*N$3))*(1+(N$4-N$5))))) -> 2120152.3 | O11: =IF($G11="","",IF($G11=1,(($C$2+$H11)*O$3)*(1+(O$4-O$5)),((O10+($H11*O$3))*(1+(O$4-O$5))))) -> 0 | P11: =IF($G11="","",IF($G11=1,(($C$2+$H11)*P$3)*(1+(P$4-P$5)),((P10+($H11*P$3))*(1+(P$4-P$5))))) -> 0 | ... T11: =IF($G11="","",IF($G11=1,(($C$2+$H11)*T$3)*(1+(T$4-T$5)),((T10+($H11*T$3))*(1+(T$4-T$5))))) -> 0 | U11: =IF(G11="","",SUM(I11,K11,M11,O11,Q11,S11)) -> 11536200 | V11: =IF(H11="","",SUM(J11,L11,N11,P11,R11,T11)) -> 11110858 | W11: =IF($G11="","",IF($G11=1,(($C$2+$H11)*W$3)*(1+(W$4-W$5)),((W10+($H11*W$3))*(1+(W$4-W$5))))) -> 11534760 | X11: =IF($G11="","",IF($G11=1,(($C$2+$H11)*X$3)*(1+(X$4-X$5)),((X10+($H11*X$3))*(1+(X$4-X$5))))) -> 11109329 | Y11: =IF($G11="","",IF($G11=1,(U11-$C$2-H11)/($C$2+H11),(U11-U10-H11)/(U10+H11))) -> 0.074134078 | Z11: =IF($G11="","",IF($G11=1,(V11-$C$2-H11)/($C$2+H11),(V11-V10-H11)/(V10+H11))) -> 0.054153145 | AA11: =IF($G11="","",Z11-Y11) -> -0.019980934 | AB11: =IF($G11="","",IF($G11=1,(W11-$C$2-H11)/($C$2+H11),(W11-W10-H11)/(W10+H11))) -> 0.074 | AC11: =IF($G11="","",IF($G11=1,(X11-$C$2-H11)/($C$2+H11),(X11-X10-H11)/(X10+H11))) -> 0.054008 | AD11: =IF($G11="","",AC11-AB11) -> -0.019992 | AE11: =IF($G11="","",IF($G11=1,Y11,(1+Y11)*(1+AE10)-1)) -> 0.15362 | AF11: =IF($G11="","",IF($G11=1,Z11,(1+Z11)*(1+AF10)-1)) -> 0.11108585 | AG11: =IF($G11="","",AF11-AE11) -> -0.042534152 | AH11: =IF($G11="","",IF($G11=1,AB11,(1+AB11)*(1+AH10)-1)) -> 0.153476 | AI11: =IF($G11="","",IF($G11=1,AC11,(1+AC11)*(1+AI10)-1)) -> 0.11093286 | AJ11: =IF($G11="","",AI11-AH11) -> -0.042543136 | AK11: =IF($G11="","",(1+AE11)^(1/G11)-1) -> 0.074067037 | AL11: =IF($G11="","",(1+AF11)^(1/G11)-1) -> 0.05408057 | AM11: =IF($G11="","",AL11-AK11) -> -0.019986467 | AN11: =IF($G11="","",(1+AH11)^(1/G11)-1) -> 0.074 | AO11: =IF($G11="","",(1+AI11)^(1/G11)-1) -> 0.054008 | AP11: =IF($G11="","",AO11-AN11) -> -0.019992
B12: PPLI Start Up Costs | G12: 3 | H12: =IF(G12="","",SUMIFS(Add_Contributions[[#All],[Amount ($)]],Add_Contributions[[#All],[Year]],G12)) -> 0 | I12: =IF($G12="","",IF($G12=1,(($C$2+$H12)*I$3)*(1+(I$4-I$5)),((I11+($H12*I$3))*(1+(I$4-I$5))))) -> 8817984 | J12: =IF($G12="","",IF($G12=1,(($C$2+$H12)*J$3)*(1+(J$4-J$5)),((J11+($H12*J$3))*(1+(J$4-J$5))))) -> 8359784.3 | K12: =IF($G12="","",IF($G12=1,(($C$2+$H12)*K$3)*(1+(K$4-K$5)),((K11+($H12*K$3))*(1+(K$4-K$5))))) -> 0 | L12: =IF($G12="","",IF($G12=1,(($C$2+$H12)*L$3)*(1+(L$4-L$5)),((L11+($H12*L$3))*(1+(L$4-L$5))))) -> 0 | M12: =IF($G12="","",IF($G12=1,(($C$2+$H12)*M$3)*(1+(M$4-M$5)),((M11+($H12*M$3))*(1+(M$4-M$5))))) -> 2315250 | N12: =IF($G12="","",IF($G12=1,(($C$2+$H12)*N$3)*(1+(N$4-N$5)),((N11+($H12*N$3))*(1+(N$4-N$5))))) -> 2182908.8 | O12: =IF($G12="","",IF($G12=1,(($C$2+$H12)*O$3)*(1+(O$4-O$5)),((O11+($H12*O$3))*(1+(O$4-O$5))))) -> 0 | P12: =IF($G12="","",IF($G12=1,(($C$2+$H12)*P$3)*(1+(P$4-P$5)),((P11+($H12*P$3))*(1+(P$4-P$5))))) -> 0 | ... T12: =IF($G12="","",IF($G12=1,(($C$2+$H12)*T$3)*(1+(T$4-T$5)),((T11+($H12*T$3))*(1+(T$4-T$5))))) -> 0 | U12: =IF(G12="","",SUM(I12,K12,M12,O12,Q12,S12)) -> 12392946 | V12: =IF(H12="","",SUM(J12,L12,N12,P12,R12,T12)) -> 11714132 | W12: =IF($G12="","",IF($G12=1,(($C$2+$H12)*W$3)*(1+(W$4-W$5)),((W11+($H12*W$3))*(1+(W$4-W$5))))) -> 12388332 | X12: =IF($G12="","",IF($G12=1,(($C$2+$H12)*X$3)*(1+(X$4-X$5)),((X11+($H12*X$3))*(1+(X$4-X$5))))) -> 11709321 | Y12: =IF($G12="","",IF($G12=1,(U12-$C$2-H12)/($C$2+H12),(U12-U11-H12)/(U11+H12))) -> 0.074265876 | Z12: =IF($G12="","",IF($G12=1,(V12-$C$2-H12)/($C$2+H12),(V12-V11-H12)/(V11+H12))) -> 0.054295844 | AA12: =IF($G12="","",Z12-Y12) -> -0.019970033 | AB12: =IF($G12="","",IF($G12=1,(W12-$C$2-H12)/($C$2+H12),(W12-W11-H12)/(W11+H12))) -> 0.074 | AC12: =IF($G12="","",IF($G12=1,(X12-$C$2-H12)/($C$2+H12),(X12-X11-H12)/(X11+H12))) -> 0.054008 | AD12: =IF($G12="","",AC12-AB12) -> -0.019992 | AE12: =IF($G12="","",IF($G12=1,Y12,(1+Y12)*(1+AE11)-1)) -> 0.2392946 | AF12: =IF($G12="","",IF($G12=1,Z12,(1+Z12)*(1+AF11)-1)) -> 0.17141319 | AG12: =IF($G12="","",AF12-AE12) -> -0.067881409 | AH12: =IF($G12="","",IF($G12=1,AB12,(1+AB12)*(1+AH11)-1)) -> 0.23883322 | AI12: =IF($G12="","",IF($G12=1,AC12,(1+AC12)*(1+AI11)-1)) -> 0.17093213 | AJ12: =IF($G12="","",AI12-AH12) -> -0.067901098 | AK12: =IF($G12="","",(1+AE12)^(1/G12)-1) -> 0.074133313 | AL12: =IF($G12="","",(1+AF12)^(1/G12)-1) -> 0.054152323 | AM12: =IF($G12="","",AL12-AK12) -> -0.01998099 | AN12: =IF($G12="","",(1+AH12)^(1/G12)-1) -> 0.074 | AO12: =IF($G12="","",(1+AI12)^(1/G12)-1) -> 0.054008 | AP12: =IF($G12="","",AO12-AN12) -> -0.019992
G13: 4 | H13: =IF(G13="","",SUMIFS(Add_Contributions[[#All],[Amount ($)]],Add_Contributions[[#All],[Year]],G13)) -> 0 | I13: =IF($G13="","",IF($G13=1,(($C$2+$H13)*I$3)*(1+(I$4-I$5)),((I12+($H13*I$3))*(1+(I$4-I$5))))) -> 9523422.7 | J13: =IF($G13="","",IF($G13=1,(($C$2+$H13)*J$3)*(1+(J$4-J$5)),((J12+($H13*J$3))*(1+(J$4-J$5))))) -> 8869396.7 | K13: =IF($G13="","",IF($G13=1,(($C$2+$H13)*K$3)*(1+(K$4-K$5)),((K12+($H13*K$3))*(1+(K$4-K$5))))) -> 0 | L13: =IF($G13="","",IF($G13=1,(($C$2+$H13)*L$3)*(1+(L$4-L$5)),((L12+($H13*L$3))*(1+(L$4-L$5))))) -> 0 | M13: =IF($G13="","",IF($G13=1,(($C$2+$H13)*M$3)*(1+(M$4-M$5)),((M12+($H13*M$3))*(1+(M$4-M$5))))) -> 2431012.5 | N13: =IF($G13="","",IF($G13=1,(($C$2+$H13)*N$3)*(1+(N$4-N$5)),((N12+($H13*N$3))*(1+(N$4-N$5))))) -> 2247522.9 | O13: =IF($G13="","",IF($G13=1,(($C$2+$H13)*O$3)*(1+(O$4-O$5)),((O12+($H13*O$3))*(1+(O$4-O$5))))) -> 0 | P13: =IF($G13="","",IF($G13=1,(($C$2+$H13)*P$3)*(1+(P$4-P$5)),((P12+($H13*P$3))*(1+(P$4-P$5))))) -> 0 | ... T13: =IF($G13="","",IF($G13=1,(($C$2+$H13)*T$3)*(1+(T$4-T$5)),((T12+($H13*T$3))*(1+(T$4-T$5))))) -> 0 | U13: =IF(G13="","",SUM(I13,K13,M13,O13,Q13,S13)) -> 13314924 | V13: =IF(H13="","",SUM(J13,L13,N13,P13,R13,T13)) -> 12351804 | W13: =IF($G13="","",IF($G13=1,(($C$2+$H13)*W$3)*(1+(W$4-W$5)),((W12+($H13*W$3))*(1+(W$4-W$5))))) -> 13305069 | X13: =IF($G13="","",IF($G13=1,(($C$2+$H13)*X$3)*(1+(X$4-X$5)),((X12+($H13*X$3))*(1+(X$4-X$5))))) -> 12341718 | Y13: =IF($G13="","",IF($G13=1,(U13-$C$2-H13)/($C$2+H13),(U13-U12-H13)/(U12+H13))) -> 0.0743954 | Z13: =IF($G13="","",IF($G13=1,(V13-$C$2-H13)/($C$2+H13),(V13-V12-H13)/(V12+H13))) -> 0.054436102 | AA13: =IF($G13="","",Z13-Y13) -> -0.019959299 | AB13: =IF($G13="","",IF($G13=1,(W13-$C$2-H13)/($C$2+H13),(W13-W12-H13)/(W12+H13))) -> 0.074 | AC13: =IF($G13="","",IF($G13=1,(X13-$C$2-H13)/($C$2+H13),(X13-X12-H13)/(X12+H13))) -> 0.054008 | AD13: =IF($G13="","",AC13-AB13) -> -0.019992 | AE13: =IF($G13="","",IF($G13=1,Y13,(1+Y13)*(1+AE12)-1)) -> 0.33149242 | AF13: =IF($G13="","",IF($G13=1,Z13,(1+Z13)*(1+AF12)-1)) -> 0.23518036 | AG13: =IF($G13="","",AF13-AE13) -> -0.096312059 | AH13: =IF($G13="","",IF($G13=1,AB13,(1+AB13)*(1+AH12)-1)) -> 0.33050688 | AI13: =IF($G13="","",IF($G13=1,AC13,(1+AC13)*(1+AI12)-1)) -> 0.23417183 | AJ13: =IF($G13="","",AI13-AH13) -> -0.096335054 | AK13: =IF($G13="","",(1+AE13)^(1/G13)-1) -> 0.074198829 | AL13: =IF($G13="","",(1+AF13)^(1/G13)-1) -> 0.05422326 | AM13: =IF($G13="","",AL13-AK13) -> -0.019975568 | AN13: =IF($G13="","",(1+AH13)^(1/G13)-1) -> 0.074 | AO13: =IF($G13="","",(1+AI13)^(1/G13)-1) -> 0.054008 | AP13: =IF($G13="","",AO13-AN13) -> -0.019992
B14: Federal Income Tax | C14: =Page!C17 -> 0.37 | G14: 5 | H14: =IF(G14="","",SUMIFS(Add_Contributions[[#All],[Amount ($)]],Add_Contributions[[#All],[Year]],G14)) -> 0 | I14: =IF($G14="","",IF($G14=1,(($C$2+$H14)*I$3)*(1+(I$4-I$5)),((I13+($H14*I$3))*(1+(I$4-I$5))))) -> 10285297 | J14: =IF($G14="","",IF($G14=1,(($C$2+$H14)*J$3)*(1+(J$4-J$5)),((J13+($H14*J$3))*(1+(J$4-J$5))))) -> 9410075.2 | K14: =IF($G14="","",IF($G14=1,(($C$2+$H14)*K$3)*(1+(K$4-K$5)),((K13+($H14*K$3))*(1+(K$4-K$5))))) -> 0 | L14: =IF($G14="","",IF($G14=1,(($C$2+$H14)*L$3)*(1+(L$4-L$5)),((L13+($H14*L$3))*(1+(L$4-L$5))))) -> 0 | M14: =IF($G14="","",IF($G14=1,(($C$2+$H14)*M$3)*(1+(M$4-M$5)),((M13+($H14*M$3))*(1+(M$4-M$5))))) -> 2552563.1 | N14: =IF($G14="","",IF($G14=1,(($C$2+$H14)*N$3)*(1+(N$4-N$5)),((N13+($H14*N$3))*(1+(N$4-N$5))))) -> 2314049.6 | O14: =IF($G14="","",IF($G14=1,(($C$2+$H14)*O$3)*(1+(O$4-O$5)),((O13+($H14*O$3))*(1+(O$4-O$5))))) -> 0 | P14: =IF($G14="","",IF($G14=1,(($C$2+$H14)*P$3)*(1+(P$4-P$5)),((P13+($H14*P$3))*(1+(P$4-P$5))))) -> 0 | ... T14: =IF($G14="","",IF($G14=1,(($C$2+$H14)*T$3)*(1+(T$4-T$5)),((T13+($H14*T$3))*(1+(T$4-T$5))))) -> 0 | U14: =IF(G14="","",SUM(I14,K14,M14,O14,Q14,S14)) -> 14307188 | V14: =IF(H14="","",SUM(J14,L14,N14,P14,R14,T14)) -> 13025890 | W14: =IF($G14="","",IF($G14=1,(($C$2+$H14)*W$3)*(1+(W$4-W$5)),((W13+($H14*W$3))*(1+(W$4-W$5))))) -> 14289644 | X14: =IF($G14="","",IF($G14=1,(($C$2+$H14)*X$3)*(1+(X$4-X$5)),((X13+($H14*X$3))*(1+(X$4-X$5))))) -> 13008270 | Y14: =IF($G14="","",IF($G14=1,(U14-$C$2-H14)/($C$2+H14),(U14-U13-H14)/(U13+H14))) -> 0.074522659 | Z14: =IF($G14="","",IF($G14=1,(V14-$C$2-H14)/($C$2+H14),(V14-V13-H14)/(V13+H14))) -> 0.054573926 | AA14: =IF($G14="","",Z14-Y14) -> -0.019948733 | AB14: =IF($G14="","",IF($G14=1,(W14-$C$2-H14)/($C$2+H14),(W14-W13-H14)/(W13+H14))) -> 0.074 | AC14: =IF($G14="","",IF($G14=1,(X14-$C$2-H14)/($C$2+H14),(X14-X13-H14)/(X13+H14))) -> 0.054008 | AD14: =IF($G14="","",AC14-AB14) -> -0.019992 | AE14: =IF($G14="","",IF($G14=1,Y14,(1+Y14)*(1+AE13)-1)) -> 0.43071877 | AF14: =IF($G14="","",IF($G14=1,Z14,(1+Z14)*(1+AF13)-1)) -> 0.302589 | AG14: =IF($G14="","",AF14-AE14) -> -0.12812977 | AH14: =IF($G14="","",IF($G14=1,AB14,(1+AB14)*(1+AH13)-1)) -> 0.42896439 | AI14: =IF($G14="","",IF($G14=1,AC14,(1+AC14)*(1+AI13)-1)) -> 0.30082698 | AJ14: =IF($G14="","",AI14-AH14) -> -0.12813741 | AK14: =IF($G14="","",(1+AE14)^(1/G14)-1) -> 0.074263587 | AL14: =IF($G14="","",(1+AF14)^(1/G14)-1) -> 0.054293384 | AM14: =IF($G14="","",AL14-AK14) -> -0.019970203 | AN14: =IF($G14="","",(1+AH14)^(1/G14)-1) -> 0.074 | AO14: =IF($G14="","",(1+AI14)^(1/G14)-1) -> 0.054008 | AP14: =IF($G14="","",AO14-AN14) -> -0.019992
B15: Capital Gains Tax | C15: =Page!C18 -> 0.2 | G15: 6 | H15: =IF(G15="","",SUMIFS(Add_Contributions[[#All],[Amount ($)]],Add_Contributions[[#All],[Year]],G15)) -> 0 | I15: =IF($G15="","",IF($G15=1,(($C$2+$H15)*I$3)*(1+(I$4-I$5)),((I14+($H15*I$3))*(1+(I$4-I$5))))) -> 11108120 | J15: =IF($G15="","",IF($G15=1,(($C$2+$H15)*J$3)*(1+(J$4-J$5)),((J14+($H15*J$3))*(1+(J$4-J$5))))) -> 9983713.4 | K15: =IF($G15="","",IF($G15=1,(($C$2+$H15)*K$3)*(1+(K$4-K$5)),((K14+($H15*K$3))*(1+(K$4-K$5))))) -> 0 | L15: =IF($G15="","",IF($G15=1,(($C$2+$H15)*L$3)*(1+(L$4-L$5)),((L14+($H15*L$3))*(1+(L$4-L$5))))) -> 0 | M15: =IF($G15="","",IF($G15=1,(($C$2+$H15)*M$3)*(1+(M$4-M$5)),((M14+($H15*M$3))*(1+(M$4-M$5))))) -> 2680191.3 | N15: =IF($G15="","",IF($G15=1,(($C$2+$H15)*N$3)*(1+(N$4-N$5)),((N14+($H15*N$3))*(1+(N$4-N$5))))) -> 2382545.5 | O15: =IF($G15="","",IF($G15=1,(($C$2+$H15)*O$3)*(1+(O$4-O$5)),((O14+($H15*O$3))*(1+(O$4-O$5))))) -> 0 | P15: =IF($G15="","",IF($G15=1,(($C$2+$H15)*P$3)*(1+(P$4-P$5)),((P14+($H15*P$3))*(1+(P$4-P$5))))) -> 0 | ... T15: =IF($G15="","",IF($G15=1,(($C$2+$H15)*T$3)*(1+(T$4-T$5)),((T14+($H15*T$3))*(1+(T$4-T$5))))) -> 0 | U15: =IF(G15="","",SUM(I15,K15,M15,O15,Q15,S15)) -> 15375186 | V15: =IF(H15="","",SUM(J15,L15,N15,P15,R15,T15)) -> 13738528 | W15: =IF($G15="","",IF($G15=1,(($C$2+$H15)*W$3)*(1+(W$4-W$5)),((W14+($H15*W$3))*(1+(W$4-W$5))))) -> 15347078 | X15: =IF($G15="","",IF($G15=1,(($C$2+$H15)*X$3)*(1+(X$4-X$5)),((X14+($H15*X$3))*(1+(X$4-X$5))))) -> 13710820 | Y15: =IF($G15="","",IF($G15=1,(U15-$C$2-H15)/($C$2+H15),(U15-U14-H15)/(U14+H15))) -> 0.074647663 | Z15: =IF($G15="","",IF($G15=1,(V15-$C$2-H15)/($C$2+H15),(V15-V14-H15)/(V14+H15))) -> 0.054709325 | AA15: =IF($G15="","",Z15-Y15) -> -0.019938337 | AB15: =IF($G15="","",IF($G15=1,(W15-$C$2-H15)/($C$2+H15),(W15-W14-H15)/(W14+H15))) -> 0.074 | AC15: =IF($G15="","",IF($G15=1,(X15-$C$2-H15)/($C$2+H15),(X15-X14-H15)/(X14+H15))) -> 0.054008 | AD15: =IF($G15="","",AC15-AB15) -> -0.019992 | AE15: =IF($G15="","",IF($G15=1,Y15,(1+Y15)*(1+AE14)-1)) -> 0.53751859 | AF15: =IF($G15="","",IF($G15=1,Z15,(1+Z15)*(1+AF14)-1)) -> 0.37385277 | AG15: =IF($G15="","",AF15-AE15) -> -0.16366582 | AH15: =IF($G15="","",IF($G15=1,AB15,(1+AB15)*(1+AH14)-1)) -> 0.53470776 | AI15: =IF($G15="","",IF($G15=1,AC15,(1+AC15)*(1+AI14)-1)) -> 0.37108204 | AJ15: =IF($G15="","",AI15-AH15) -> -0.16362571 | AK15: =IF($G15="","",(1+AE15)^(1/G15)-1) -> 0.07432759 | AL15: =IF($G15="","",(1+AF15)^(1/G15)-1) -> 0.054362696 | AM15: =IF($G15="","",AL15-AK15) -> -0.019964894 | AN15: =IF($G15="","",(1+AH15)^(1/G15)-1) -> 0.074 | AO15: =IF($G15="","",(1+AI15)^(1/G15)-1) -> 0.054008 | AP15: =IF($G15="","",AO15-AN15) -> -0.019992
B16: Net Investment Income Tax | C16: =Page!C19 -> 0.038 | G16: 7 | H16: =IF(G16="","",SUMIFS(Add_Contributions[[#All],[Amount ($)]],Add_Contributions[[#All],[Year]],G16)) -> 0 | I16: =IF($G16="","",IF($G16=1,(($C$2+$H16)*I$3)*(1+(I$4-I$5)),((I15+($H16*I$3))*(1+(I$4-I$5))))) -> 11996770 | J16: =IF($G16="","",IF($G16=1,(($C$2+$H16)*J$3)*(1+(J$4-J$5)),((J15+($H16*J$3))*(1+(J$4-J$5))))) -> 10592321 | K16: =IF($G16="","",IF($G16=1,(($C$2+$H16)*K$3)*(1+(K$4-K$5)),((K15+($H16*K$3))*(1+(K$4-K$5))))) -> 0 | L16: =IF($G16="","",IF($G16=1,(($C$2+$H16)*L$3)*(1+(L$4-L$5)),((L15+($H16*L$3))*(1+(L$4-L$5))))) -> 0 | M16: =IF($G16="","",IF($G16=1,(($C$2+$H16)*M$3)*(1+(M$4-M$5)),((M15+($H16*M$3))*(1+(M$4-M$5))))) -> 2814200.8 | N16: =IF($G16="","",IF($G16=1,(($C$2+$H16)*N$3)*(1+(N$4-N$5)),((N15+($H16*N$3))*(1+(N$4-N$5))))) -> 2453068.8 | O16: =IF($G16="","",IF($G16=1,(($C$2+$H16)*O$3)*(1+(O$4-O$5)),((O15+($H16*O$3))*(1+(O$4-O$5))))) -> 0 | P16: =IF($G16="","",IF($G16=1,(($C$2+$H16)*P$3)*(1+(P$4-P$5)),((P15+($H16*P$3))*(1+(P$4-P$5))))) -> 0 | ... T16: =IF($G16="","",IF($G16=1,(($C$2+$H16)*T$3)*(1+(T$4-T$5)),((T15+($H16*T$3))*(1+(T$4-T$5))))) -> 0 | U16: =IF(G16="","",SUM(I16,K16,M16,O16,Q16,S16)) -> 16524795 | V16: =IF(H16="","",SUM(J16,L16,N16,P16,R16,T16)) -> 14491980 | W16: =IF($G16="","",IF($G16=1,(($C$2+$H16)*W$3)*(1+(W$4-W$5)),((W15+($H16*W$3))*(1+(W$4-W$5))))) -> 16482761 | X16: =IF($G16="","",IF($G16=1,(($C$2+$H16)*X$3)*(1+(X$4-X$5)),((X15+($H16*X$3))*(1+(X$4-X$5))))) -> 14451314 | Y16: =IF($G16="","",IF($G16=1,(U16-$C$2-H16)/($C$2+H16),(U16-U15-H16)/(U15+H16))) -> 0.074770422 | Z16: =IF($G16="","",IF($G16=1,(V16-$C$2-H16)/($C$2+H16),(V16-V15-H16)/(V15+H16))) -> 0.05484231 | AA16: =IF($G16="","",Z16-Y16) -> -0.019928112 | AB16: =IF($G16="","",IF($G16=1,(W16-$C$2-H16)/($C$2+H16),(W16-W15-H16)/(W15+H16))) -> 0.074 | AC16: =IF($G16="","",IF($G16=1,(X16-$C$2-H16)/($C$2+H16),(X16-X15-H16)/(X15+H16))) -> 0.054008 | AD16: =IF($G16="","",AC16-AB16) -> -0.019992 | AE16: =IF($G16="","",IF($G16=1,Y16,(1+Y16)*(1+AE15)-1)) -> 0.6524795 | AF16: =IF($G16="","",IF($G16=1,Z16,(1+Z16)*(1+AF15)-1)) -> 0.44919803 | AG16: =IF($G16="","",AF16-AE16) -> -0.20328147 | AH16: =IF($G16="","",IF($G16=1,AB16,(1+AB16)*(1+AH15)-1)) -> 0.64827613 | AI16: =IF($G16="","",IF($G16=1,AC16,(1+AC16)*(1+AI15)-1)) -> 0.44513144 | AJ16: =IF($G16="","",AI16-AH16) -> -0.20314469 | AK16: =IF($G16="","",(1+AE16)^(1/G16)-1) -> 0.074390841 | AL16: =IF($G16="","",(1+AF16)^(1/G16)-1) -> 0.054431199 | AM16: =IF($G16="","",AL16-AK16) -> -0.019959641 | AN16: =IF($G16="","",(1+AH16)^(1/G16)-1) -> 0.074 | AO16: =IF($G16="","",(1+AI16)^(1/G16)-1) -> 0.054008 | AP16: =IF($G16="","",AO16-AN16) -> -0.019992
B17: State Income Tax | G17: 8 | H17: =IF(G17="","",SUMIFS(Add_Contributions[[#All],[Amount ($)]],Add_Contributions[[#All],[Year]],G17)) -> 0 | I17: =IF($G17="","",IF($G17=1,(($C$2+$H17)*I$3)*(1+(I$4-I$5)),((I16+($H17*I$3))*(1+(I$4-I$5))))) -> 12956511 | J17: =IF($G17="","",IF($G17=1,(($C$2+$H17)*J$3)*(1+(J$4-J$5)),((J16+($H17*J$3))*(1+(J$4-J$5))))) -> 11238028 | K17: =IF($G17="","",IF($G17=1,(($C$2+$H17)*K$3)*(1+(K$4-K$5)),((K16+($H17*K$3))*(1+(K$4-K$5))))) -> 0 | L17: =IF($G17="","",IF($G17=1,(($C$2+$H17)*L$3)*(1+(L$4-L$5)),((L16+($H17*L$3))*(1+(L$4-L$5))))) -> 0 | M17: =IF($G17="","",IF($G17=1,(($C$2+$H17)*M$3)*(1+(M$4-M$5)),((M16+($H17*M$3))*(1+(M$4-M$5))))) -> 2954910.9 | N17: =IF($G17="","",IF($G17=1,(($C$2+$H17)*N$3)*(1+(N$4-N$5)),((N16+($H17*N$3))*(1+(N$4-N$5))))) -> 2525679.7 | O17: =IF($G17="","",IF($G17=1,(($C$2+$H17)*O$3)*(1+(O$4-O$5)),((O16+($H17*O$3))*(1+(O$4-O$5))))) -> 0 | P17: =IF($G17="","",IF($G17=1,(($C$2+$H17)*P$3)*(1+(P$4-P$5)),((P16+($H17*P$3))*(1+(P$4-P$5))))) -> 0 | ... T17: =IF($G17="","",IF($G17=1,(($C$2+$H17)*T$3)*(1+(T$4-T$5)),((T16+($H17*T$3))*(1+(T$4-T$5))))) -> 0 | U17: =IF(G17="","",SUM(I17,K17,M17,O17,Q17,S17)) -> 17762353 | V17: =IF(H17="","",SUM(J17,L17,N17,P17,R17,T17)) -> 15288646 | W17: =IF($G17="","",IF($G17=1,(($C$2+$H17)*W$3)*(1+(W$4-W$5)),((W16+($H17*W$3))*(1+(W$4-W$5))))) -> 17702486 | X17: =IF($G17="","",IF($G17=1,(($C$2+$H17)*X$3)*(1+(X$4-X$5)),((X16+($H17*X$3))*(1+(X$4-X$5))))) -> 15231801 | Y17: =IF($G17="","",IF($G17=1,(U17-$C$2-H17)/($C$2+H17),(U17-U16-H17)/(U16+H17))) -> 0.074890949 | Z17: =IF($G17="","",IF($G17=1,(V17-$C$2-H17)/($C$2+H17),(V17-V16-H17)/(V16+H17))) -> 0.054972892 | AA17: =IF($G17="","",Z17-Y17) -> -0.019918057 | AB17: =IF($G17="","",IF($G17=1,(W17-$C$2-H17)/($C$2+H17),(W17-W16-H17)/(W16+H17))) -> 0.074 | AC17: =IF($G17="","",IF($G17=1,(X17-$C$2-H17)/($C$2+H17),(X17-X16-H17)/(X16+H17))) -> 0.054008 | AD17: =IF($G17="","",AC17-AB17) -> -0.019992 | AE17: =IF($G17="","",IF($G17=1,Y17,(1+Y17)*(1+AE16)-1)) -> 0.77623526 | AF17: =IF($G17="","",IF($G17=1,Z17,(1+Z17)*(1+AF16)-1)) -> 0.52886463 | AG17: =IF($G17="","",AF17-AE17) -> -0.24737063 | AH17: =IF($G17="","",IF($G17=1,AB17,(1+AB17)*(1+AH16)-1)) -> 0.77024856 | AI17: =IF($G17="","",IF($G17=1,AC17,(1+AC17)*(1+AI16)-1)) -> 0.5231801 | AJ17: =IF($G17="","",AI17-AH17) -> -0.24706846 | AK17: =IF($G17="","",(1+AE17)^(1/G17)-1) -> 0.074453341 | AL17: =IF($G17="","",(1+AF17)^(1/G17)-1) -> 0.054498896 | AM17: =IF($G17="","",AL17-AK17) -> -0.019954446 | AN17: =IF($G17="","",(1+AH17)^(1/G17)-1) -> 0.074 | AO17: =IF($G17="","",(1+AI17)^(1/G17)-1) -> 0.054008 | AP17: =IF($G17="","",AO17-AN17) -> -0.019992
G18: 9 | H18: =IF(G18="","",SUMIFS(Add_Contributions[[#All],[Amount ($)]],Add_Contributions[[#All],[Year]],G18)) -> 0 | I18: =IF($G18="","",IF($G18=1,(($C$2+$H18)*I$3)*(1+(I$4-I$5)),((I17+($H18*I$3))*(1+(I$4-I$5))))) -> 13993032 | J18: =IF($G18="","",IF($G18=1,(($C$2+$H18)*J$3)*(1+(J$4-J$5)),((J17+($H18*J$3))*(1+(J$4-J$5))))) -> 11923099 | K18: =IF($G18="","",IF($G18=1,(($C$2+$H18)*K$3)*(1+(K$4-K$5)),((K17+($H18*K$3))*(1+(K$4-K$5))))) -> 0 | L18: =IF($G18="","",IF($G18=1,(($C$2+$H18)*L$3)*(1+(L$4-L$5)),((L17+($H18*L$3))*(1+(L$4-L$5))))) -> 0 | M18: =IF($G18="","",IF($G18=1,(($C$2+$H18)*M$3)*(1+(M$4-M$5)),((M17+($H18*M$3))*(1+(M$4-M$5))))) -> 3102656.4 | N18: =IF($G18="","",IF($G18=1,(($C$2+$H18)*N$3)*(1+(N$4-N$5)),((N17+($H18*N$3))*(1+(N$4-N$5))))) -> 2600439.8 | O18: =IF($G18="","",IF($G18=1,(($C$2+$H18)*O$3)*(1+(O$4-O$5)),((O17+($H18*O$3))*(1+(O$4-O$5))))) -> 0 | P18: =IF($G18="","",IF($G18=1,(($C$2+$H18)*P$3)*(1+(P$4-P$5)),((P17+($H18*P$3))*(1+(P$4-P$5))))) -> 0 | ... T18: =IF($G18="","",IF($G18=1,(($C$2+$H18)*T$3)*(1+(T$4-T$5)),((T17+($H18*T$3))*(1+(T$4-T$5))))) -> 0 | U18: =IF(G18="","",SUM(I18,K18,M18,O18,Q18,S18)) -> 19094693 | V18: =IF(H18="","",SUM(J18,L18,N18,P18,R18,T18)) -> 16131067 | W18: =IF($G18="","",IF($G18=1,(($C$2+$H18)*W$3)*(1+(W$4-W$5)),((W17+($H18*W$3))*(1+(W$4-W$5))))) -> 19012470 | X18: =IF($G18="","",IF($G18=1,(($C$2+$H18)*X$3)*(1+(X$4-X$5)),((X17+($H18*X$3))*(1+(X$4-X$5))))) -> 16054440 | Y18: =IF($G18="","",IF($G18=1,(U18-$C$2-H18)/($C$2+H18),(U18-U17-H18)/(U17+H18))) -> 0.075009258 | Z18: =IF($G18="","",IF($G18=1,(V18-$C$2-H18)/($C$2+H18),(V18-V17-H18)/(V17+H18))) -> 0.055101084 | AA18: =IF($G18="","",Z18-Y18) -> -0.019908174 | AB18: =IF($G18="","",IF($G18=1,(W18-$C$2-H18)/($C$2+H18),(W18-W17-H18)/(W17+H18))) -> 0.074 | AC18: =IF($G18="","",IF($G18=1,(X18-$C$2-H18)/($C$2+H18),(X18-X17-H18)/(X17+H18))) -> 0.054008 | AD18: =IF($G18="","",AC18-AB18) -> -0.019992 | AE18: =IF($G18="","",IF($G18=1,Y18,(1+Y18)*(1+AE17)-1)) -> 0.90946934 | AF18: =IF($G18="","",IF($G18=1,Z18,(1+Z18)*(1+AF17)-1)) -> 0.61310673 | AG18: =IF($G18="","",AF18-AE18) -> -0.29636262 | AH18: =IF($G18="","",IF($G18=1,AB18,(1+AB18)*(1+AH17)-1)) -> 0.90124696 | AI18: =IF($G18="","",IF($G18=1,AC18,(1+AC18)*(1+AI17)-1)) -> 0.60544401 | AJ18: =IF($G18="","",AI18-AH18) -> -0.29580295 | AK18: =IF($G18="","",(1+AE18)^(1/G18)-1) -> 0.074515096 | AL18: =IF($G18="","",(1+AF18)^(1/G18)-1) -> 0.054565788 | AM18: =IF($G18="","",AL18-AK18) -> -0.019949307 | AN18: =IF($G18="","",(1+AH18)^(1/G18)-1) -> 0.074 | AO18: =IF($G18="","",(1+AI18)^(1/G18)-1) -> 0.054008 | AP18: =IF($G18="","",AO18-AN18) -> -0.019992
G19: 10 | H19: =IF(G19="","",SUMIFS(Add_Contributions[[#All],[Amount ($)]],Add_Contributions[[#All],[Year]],G19)) -> 0 | I19: =IF($G19="","",IF($G19=1,(($C$2+$H19)*I$3)*(1+(I$4-I$5)),((I18+($H19*I$3))*(1+(I$4-I$5))))) -> 15112475 | J19: =IF($G19="","",IF($G19=1,(($C$2+$H19)*J$3)*(1+(J$4-J$5)),((J18+($H19*J$3))*(1+(J$4-J$5))))) -> 12649931 | K19: =IF($G19="","",IF($G19=1,(($C$2+$H19)*K$3)*(1+(K$4-K$5)),((K18+($H19*K$3))*(1+(K$4-K$5))))) -> 0 | L19: =IF($G19="","",IF($G19=1,(($C$2+$H19)*L$3)*(1+(L$4-L$5)),((L18+($H19*L$3))*(1+(L$4-L$5))))) -> 0 | M19: =IF($G19="","",IF($G19=1,(($C$2+$H19)*M$3)*(1+(M$4-M$5)),((M18+($H19*M$3))*(1+(M$4-M$5))))) -> 3257789.3 | N19: =IF($G19="","",IF($G19=1,(($C$2+$H19)*N$3)*(1+(N$4-N$5)),((N18+($H19*N$3))*(1+(N$4-N$5))))) -> 2677412.8 | O19: =IF($G19="","",IF($G19=1,(($C$2+$H19)*O$3)*(1+(O$4-O$5)),((O18+($H19*O$3))*(1+(O$4-O$5))))) -> 0 | P19: =IF($G19="","",IF($G19=1,(($C$2+$H19)*P$3)*(1+(P$4-P$5)),((P18+($H19*P$3))*(1+(P$4-P$5))))) -> 0 | ... T19: =IF($G19="","",IF($G19=1,(($C$2+$H19)*T$3)*(1+(T$4-T$5)),((T18+($H19*T$3))*(1+(T$4-T$5))))) -> 0 | U19: =IF(G19="","",SUM(I19,K19,M19,O19,Q19,S19)) -> 20529189 | V19: =IF(H19="","",SUM(J19,L19,N19,P19,R19,T19)) -> 17021936 | W19: =IF($G19="","",IF($G19=1,(($C$2+$H19)*W$3)*(1+(W$4-W$5)),((W18+($H19*W$3))*(1+(W$4-W$5))))) -> 20419392 | X19: =IF($G19="","",IF($G19=1,(($C$2+$H19)*X$3)*(1+(X$4-X$5)),((X18+($H19*X$3))*(1+(X$4-X$5))))) -> 16921508 | Y19: =IF($G19="","",IF($G19=1,(U19-$C$2-H19)/($C$2+H19),(U19-U18-H19)/(U18+H19))) -> 0.075125363 | Z19: =IF($G19="","",IF($G19=1,(V19-$C$2-H19)/($C$2+H19),(V19-V18-H19)/(V18+H19))) -> 0.055226902 | AA19: =IF($G19="","",Z19-Y19) -> -0.019898461 | AB19: =IF($G19="","",IF($G19=1,(W19-$C$2-H19)/($C$2+H19),(W19-W18-H19)/(W18+H19))) -> 0.074 | AC19: =IF($G19="","",IF($G19=1,(X19-$C$2-H19)/($C$2+H19),(X19-X18-H19)/(X18+H19))) -> 0.054008 | AD19: =IF($G19="","",AC19-AB19) -> -0.019992 | AE19: =IF($G19="","",IF($G19=1,Y19,(1+Y19)*(1+AE18)-1)) -> 1.0529189 | AF19: =IF($G19="","",IF($G19=1,Z19,(1+Z19)*(1+AF18)-1)) -> 0.70219362 | AG19: =IF($G19="","",AF19-AE19) -> -0.35072531 | AH19: =IF($G19="","",IF($G19=1,AB19,(1+AB19)*(1+AH18)-1)) -> 1.0419392 | AI19: =IF($G19="","",IF($G19=1,AC19,(1+AC19)*(1+AI18)-1)) -> 0.69215083 | AJ19: =IF($G19="","",AI19-AH19) -> -0.3497884 | AK19: =IF($G19="","",(1+AE19)^(1/G19)-1) -> 0.074576107 | AL19: =IF($G19="","",(1+AF19)^(1/G19)-1) -> 0.054631881 | AM19: =IF($G19="","",AL19-AK19) -> -0.019944226 | AN19: =IF($G19="","",(1+AH19)^(1/G19)-1) -> 0.074 | AO19: =IF($G19="","",(1+AI19)^(1/G19)-1) -> 0.054008 | AP19: =IF($G19="","",AO19-AN19) -> -0.019992
