Workbook
Name X_Axis: OFFSET(#REF!,0,0,'Return Simulator'!$D$48,1)

Sheet Diagram

Sheet Log-in
C4: "Platform Name"
J5: * Standalone log-in via our platform or integrated into RIA existing wealth platform
C7: Username
C10: Password
C15: Log-In

Sheet Suitability
C4: Client Profile | G4: * Final version would include a larger array of intake question/data (Data input here, would drive the similator snapshot of how Private Placement can impact future wealth)
C5: Client Name | D5: John Doe | G5: * AI driven results to show if client is/is not suitable with reasoning and other commentary
C6: Accredited Investor | D6: TRUE | G6: *Final version could be integrated to automatically pull client information from RIA Exisiting wealth platform
C7: Qualified Purchaser | D7: TRUE
C8: Interest in Private Placement | D8: TRUE | H8: * Sections (working)
I9: 1. Client Profile
C10: Investment Settings | I10: 2. Financial Snapshot
C11: Portfolio Value | D11: 10000000 | I11: 3. Legal & Compliance Qualification
C12: Time Horizon | D12: 20 | I12: 4. Exsiting Life Insurance/Annuities
I13: 5. Investment Allocation Preferences & Objectives
C14: Portfolio Allocation
C15: Stocks | D15: 0.48
C16: Bonds | D16: 0.32
C17: Alternative | D17: 0.2
C19: Return Assumptions
C20: Stocks | D20: 0.08
C21: Bonds | D21: 0.05
C22: Alternative | D22: 0.08
C25: =IF(D8=FALSE,"Not Suitable - Client Not Interested",IF(AND(D7=FALSE,D6=FALSE),"Not Suitable - Client Not An Accredited Investor/Qualified Purchaser","Client may be suitable")) -> Client may be suitable
C28: =IF(C25="Client may be suitable","Explore Impact of Private Placement","") -> Explore Impact of Private Placement

Sheet Return Simulator
B2: Back
W3: * Maybe include more unique comparison options (potentially driven by data/information from intake)
C4: Current Client Portfolio | W4: * e.g. - Comapare impact of housing solely alternatives into PPLI wrapper
C5: Projected Value | D5: ='1'!C22 -> 27153622
C6: Net | D6: ='1'!C29 -> 0.05121461
C10: 10% of Current Portfolio inside PPLI | F10: Compared to Base Case
C11: =C5 -> Projected Value | D11: ='2'!C22 -> 28098547 | F11: =_xlfn.CONCAT("+ ",TEXT(D11-$D$5,"$#,##0.00")) -> + $944,925.05
C12: =C6 -> Net | D12: ='2'!C29 -> 0.053014116 | F12: =_xlfn.CONCAT("+ ",TEXT(D12-$D$6,"0.00%")) -> + 0.18%
C14: 20% of Current Portfolio inside PPLI | F14: Compared to Base Case
C15: =C5 -> Projected Value | D15: ='3'!C22 -> 29043472 | F15: =_xlfn.CONCAT("+ ",TEXT(D15-$D$5,"$#,##0.00")) -> + $1,889,850.10
C16: =C12 -> Net | D16: ='3'!C29 -> 0.054757025 | F16: =_xlfn.CONCAT("+ ",TEXT(D16-$D$6,"0.00%")) -> + 0.35%
C18: 30% of Current Portfolio inside PPLI | F18: Compared to Base Case
C19: =C5 -> Projected Value | D19: ='4'!C22 -> 29988397 | F19: =_xlfn.CONCAT("+ ",TEXT(D19-$D$5,"$#,##0.00")) -> + $2,834,775.14
C20: =C16 -> Net | D20: ='4'!C29 -> 0.056446875 | F20: =_xlfn.CONCAT("+ ",TEXT(D20-$D$6,"0.00%")) -> + 0.52%
C22: 40% of Current Portfolio inside PPLI | F22: Compared to Base Case
C23: =C5 -> Projected Value | D23: ='5'!C22 -> 30933322 | F23: =_xlfn.CONCAT("+ ",TEXT(D23-$D$5,"$#,##0.00")) -> + $3,779,700.19
C24: =C20 -> Net | D24: ='5'!C29 -> 0.058086877 | F24: =_xlfn.CONCAT("+ ",TEXT(D24-$D$6,"0.00%")) -> + 0.69% | L24: Explore Carriers/Products
L28: Explore Education Portal
L32: Explore Other Service Providers
C46: Investment Settings | H46: Buy & Hold | W46: Rebalanced
C47: Starting Capital ($) | D47: =Suitability!D11 -> 10000000
C48: Investment Horizon (Years) | D48: =Suitability!D12 -> 20 | W48: Custom | Z48: Traditional (Taxable) | AC48: Traditional (PPLI) | AF48: Alternatives Enhanced (Taxable) | AI48: Alternatives Enhanced (PPLI)
W49: Projected Value | X49: ='1'!D22 -> 26313895 | Z49: =W49 -> Projected Value | AA49: ='2'!D22 -> 27119396 | AC49: =W49 -> Projected Value | AD49: ='3'!D22 -> 27948285 | AF49: =W49 -> Projected Value | AG49: ='4'!D22 -> 28801206 | AI49: =W49 -> Projected Value | AJ49: ='5'!D22 -> 29678817
C50: Portfolio Allocation (%) | F50: Allocation Check
C51: Stocks | D51: =Suitability!D15 -> 0.48 | F51: =IF(SUM(D51:D53)=1,"Good","Must Equal 100%") -> Good | H51: Total Return | K51: =H51 -> Total Return | N51: =K51 -> Total Return | Q51: =N51 -> Total Return | T51: =Q51 -> Total Return | W51: Total Return | Z51: =W51 -> Total Return | AC51: =Z51 -> Total Return | AF51: =AC51 -> Total Return | AI51: =AF51 -> Total Return
C52: Bonds | D52: =Suitability!D16 -> 0.32 | H52: Gross | I52: ='1'!C24 -> 3.0185061 | K52: =H52 -> Gross | L52: ='2'!C24 -> 3.0185061 | N52: =K52 -> Gross | O52: ='3'!C24 -> 3.0185061 | Q52: =N52 -> Gross | R52: ='4'!C24 -> 3.0185061 | T52: =Q52 -> Gross | U52: ='5'!C24 -> 3.0185061 | W52: Gross | X52: ='1'!D24 -> 2.8987197 | Z52: =W52 -> Gross | AA52: ='2'!D24 -> 2.8987197 | AC52: =Z52 -> Gross | AD52: ='3'!D24 -> 2.8987197 | AF52: =AC52 -> Gross | AG52: ='4'!D24 -> 2.8987197 | AI52: =AF52 -> Gross | AJ52: ='5'!D24 -> 2.8987197
C53: Alternatives | D53: =Suitability!D17 -> 0.2 | H53: Net | I53: ='1'!C25 -> 1.7153622 | K53: =H53 -> Net | L53: ='2'!C25 -> 1.8098547 | N53: =K53 -> Net | O53: ='3'!C25 -> 1.9043472 | Q53: =N53 -> Net | R53: ='4'!C25 -> 1.9988397 | T53: =Q53 -> Net | U53: ='5'!C25 -> 2.0933322 | W53: Net | X53: ='1'!D25 -> 1.6313895 | Z53: =W53 -> Net | AA53: ='2'!D25 -> 1.7119396 | AC53: =Z53 -> Net | AD53: ='3'!D25 -> 1.7948285 | AF53: =AC53 -> Net | AG53: ='4'!D25 -> 1.8801206 | AI53: =AF53 -> Net | AJ53: ='5'!D25 -> 1.9678817
H54: Drag | I54: ='1'!C26 -> -1.3031439 | K54: =H54 -> Drag | L54: ='2'!C26 -> -1.2086514 | N54: =K54 -> Drag | O54: ='3'!C26 -> -1.1141589 | Q54: =N54 -> Drag | R54: ='4'!C26 -> -1.0196664 | T54: =Q54 -> Drag | U54: ='5'!C26 -> -0.92517392 | W54: Drag | X54: ='1'!D26 -> -1.2673301 | Z54: =W54 -> Drag | AA54: ='2'!D26 -> -1.1867801 | AC54: =Z54 -> Drag | AD54: ='3'!D26 -> -1.1038911 | AF54: =AC54 -> Drag | AG54: ='4'!D26 -> -1.0185991 | AI54: =AF54 -> Drag | AJ54: ='5'!D26 -> -0.93083797
C55: Return Assumptions (%)
C56: Stocks | D56: =Suitability!D20 -> 0.08 | H56: Annualized Return | K56: =H56 -> Annualized Return | N56: =K56 -> Annualized Return | Q56: =N56 -> Annualized Return | T56: =Q56 -> Annualized Return | W56: Annualized Return | Z56: =W56 -> Annualized Return | AC56: =Z56 -> Annualized Return | AF56: =AC56 -> Annualized Return | AI56: =AF56 -> Annualized Return
C57: Bonds | D57: =Suitability!D21 -> 0.05 | H57: Gross | I57: ='1'!C28 -> 0.072020849 | K57: =H57 -> Gross | L57: ='2'!C28 -> 0.072020849 | N57: =K57 -> Gross | O57: ='3'!C28 -> 0.072020849 | Q57: =N57 -> Gross | R57: ='4'!C28 -> 0.072020849 | T57: =Q57 -> Gross | U57: ='5'!C28 -> 0.072020849 | W57: Gross | X57: ='1'!D28 -> 0.0704 | Z57: =W57 -> Gross | AA57: ='2'!D28 -> 0.0704 | AC57: =Z57 -> Gross | AD57: ='3'!D28 -> 0.0704 | AF57: =AC57 -> Gross | AG57: ='4'!D28 -> 0.0704 | AI57: =AF57 -> Gross | AJ57: ='5'!D28 -> 0.0704
C58: Alternatives | D58: =Suitability!D22 -> 0.08 | W58: Net | X58: ='1'!D29 -> 0.0495648 | Z58: =W58 -> Net | AA58: ='2'!D29 -> 0.05114832 | AC58: =Z58 -> Net | AD58: ='3'!D29 -> 0.05273184 | AF58: =AC58 -> Net | AG58: ='4'!D29 -> 0.05431536 | AI58: =AF58 -> Net | AJ58: ='5'!D29 -> 0.05589888
H59: Drag | I59: ='1'!C30 -> -0.020806239 | K59: =H59 -> Drag | L59: ='2'!C30 -> -0.019006733 | N59: =K59 -> Drag | O59: ='3'!C30 -> -0.017263824 | Q59: =N59 -> Drag | R59: ='4'!C30 -> -0.015573974 | T59: =Q59 -> Drag | U59: ='5'!C30 -> -0.013933972 | W59: Drag | X59: ='1'!D30 -> -0.0208352 | Z59: =W59 -> Drag | AA59: ='2'!D30 -> -0.01925168 | AC59: =Z59 -> Drag | AD59: ='3'!D30 -> -0.01766816 | AF59: =AC59 -> Drag | AG59: ='4'!D30 -> -0.01608464 | AI59: =AF59 -> Drag | AJ59: ='5'!D30 -> -0.01450112
C60: Tax Assumptions (%)
C61: Ordinary Income | D61: 0.37
C62: Capital Gains | D62: 0.2
C63: NIIT | D63: 0.038
C65: PPLI Allocation (%)
C66: Stocks | D66: 0
C67: Bonds | D67: 0
...

Sheet Carrier Portal
B2: Back
C4: Carrier | D4: Rating | E4: Policy Minimum | F4: Fund Name | G4: Fund Type | H4: Learn More | I4: Select Policy
C5: X | D5: 5 | E5: 1000000 | F5: A | G5: Private Equity | H5: Link | I5: FALSE
C6: X | D6: 5 | E6: 1000000 | F6: B | G6: Private Credit | H6: Link | I6: FALSE
C7: Y | D7: 3.5 | E7: 500000 | F7: C | G7: Real Estate | H7: Link | I7: FALSE
C8: Z | D8: 4.5 | E8: 2000000 | F8: D | G8: Fixed Income | H8: Link | I8: FALSE
C9: Z | D9: 4.5 | E9: 2000000 | F9: E | G9: Private Credit | H9: Link | I9: FALSE
C10: Z | D10: 4.5 | E10: 2000000 | F10: F | G10: S&P 500 Index | H10: Link | I10: FALSE
E12: Begin Policy Execution

Sheet Education Portal
B2: Back
G3: * Demo is simplified data room - Should be a place where advisors/clients can learn more about PPLI/PPVA and what it is, the steps involved, impact, legal & compliance concerns, etc.
C4: Type | D4: Learn More
C5: White Papers | D5: Link
C6: What is PPLI/PPVA | D6: Link
C7: PPLI/PPVA Compliance | D7: Link
C8: Taxes | D8: Link
C9: Estate/Trust | D9: Link

Sheet Service Providers
B2: Back
G3: * Demo is simplified - Should be a place where advisors/clients can connect to other services providers needed for the PPLI/PPVA process if not already available/provided
C4: Type | D4: Connect
C5: Estate Attornerys | D5: Link
C6: Trust Providers | D6: Link
C7: CPA's | D7: Link
C8: Taxes | D8: Link
C9: Estate/Trust | D9: Link

Sheet Policy Execution
C3: Workflow Steps
C4: 1. Advisor initiates connection with the selected carrier to start the process.
C5: 2. Carrier is notified automatically via the platform.
C6: 3. Platform facilitates secure document exchange and onboarding — including KYC, AML, and application uploads.
C7: 4. Advisor tracks underwriting progress in real time through the integrated platform dashboard.
C8: 5. Platform automatically creates a compliance trail for audit and recordkeeping, while maintaining a secure, encrypted data environment.
C9: 6. Once policy is activated, carrier data is pushed back into the platform through API connections for performance reporting and portfolio integration.
C13: * Steps are simplified for version 1 - Purpose is end-to-end integrated/streamlined process of policy selection/execution. The goal should be to make it as quick and easy as possible for the RIA/Client while offering a compliance ready and secure aduit trail

Sheet Portal-Widget
E3: Current Value | G3: 25000000 | K3: Resrouces | U3: * Standalone portal accessed via out platform or integrated into RIA Exisiting wealth platform
K5: Statements
E7: Metrics Table | K7: Policy Information
K9: Education
K11: Service Providers | W11: Carrier A | X11: =25%*$G$3 -> 6250000
W12: Carrier B | X12: =30%*$G$3 -> 7500000
K13: Contact Advisor/Carrier | W13: Carrier C | X13: =45%*$G$3 -> 11250000
O15: Chat with AI
W17: 1 | X17: 10000000
W18: 5 | X18: =X17*1.4 -> 14000000
W19: 10 | X19: =X18*1.4 -> 19600000
W20: 15 | X20: 25000000

Sheet Chart Feeder >

Sheet WA PIVOT
A1: Buy & Hold | I1: Rebalanced
D3: Current Client Portfolio | F3: 10% of Current Portfolio inside PPLI | H3: 20% of Current Portfolio inside PPLI | J3: 100% of Alternatives inside PPLI | L3: 100% of Bonds inside PPLI
A6: Row Labels | B6: Current Client Portfolio | C6: 10% of Current Portfolio inside PPLI | D6: 20% of Current Portfolio inside PPLI | E6: 30% of Current Portfolio inside PPLI | F6: 40% of Current Portfolio inside PPLI | I6: Row Labels | J6: Current Client Portfolio | K6: 10% of Current Portfolio inside PPLI | L6: 20% of Current Portfolio inside PPLI | M6: 30% of Current Portfolio inside PPLI | N6: 40% of Current Portfolio inside PPLI
A7: 1 | B7: 10495648 | C7: 10511483 | D7: 10527318 | E7: 10543154 | F7: 10558989 | I7: 1 | J7: 10495648 | K7: 10511483 | L7: 10527318 | M7: 10543154 | N7: 10558989
A8: 2 | B8: 11015863 | C8: 11049128 | D8: 11082443 | E8: 11115809 | F8: 11149224 | I8: 2 | J8: 11015863 | K8: 11049128 | L8: 11082443 | M8: 11115809 | N8: 11149224
A9: 3 | B9: 11561862 | C9: 11614272 | D9: 11666841 | E9: 11719568 | F9: 11772454 | I9: 3 | J9: 11561862 | K9: 11614272 | L9: 11666841 | M9: 11719568 | N9: 11772454
A10: 4 | B10: 12134923 | C10: 12208323 | D10: 12282055 | E10: 12356120 | F10: 12430521 | I10: 4 | J10: 12134923 | K10: 12208323 | L10: 12282055 | M10: 12356120 | N10: 12430521
A11: 5 | B11: 12736388 | C11: 12832758 | D11: 12929710 | E11: 13027248 | F11: 13125373 | I11: 5 | J11: 12736388 | K11: 12832758 | L11: 12929710 | M11: 13027248 | N11: 13125373
A12: 6 | B12: 13367665 | C12: 13489132 | D12: 13611518 | E12: 13734827 | F12: 13859066 | I12: 6 | J12: 13367665 | K12: 13489132 | L12: 13611518 | M12: 13734827 | N12: 13859066
A13: 7 | B13: 14030230 | C13: 14179078 | D13: 14329278 | E13: 14480839 | F13: 14633773 | I13: 7 | J13: 14030230 | K13: 14179078 | L13: 14329278 | M13: 14480839 | N13: 14633773
A14: 8 | B14: 14725636 | C14: 14904314 | D14: 15084887 | E14: 15267371 | F14: 15451784 | I14: 8 | J14: 14725636 | K14: 14904314 | L14: 15084887 | M14: 15267371 | N14: 15451784
A15: 9 | B15: 15455509 | C15: 15666645 | D15: 15880341 | E15: 16096624 | F15: 16315522 | I15: 9 | J15: 15455509 | K15: 15666645 | L15: 15880341 | M15: 16096624 | N15: 16315522
A16: 10 | B16: 16221558 | C16: 16467968 | D16: 16717741 | E16: 16970918 | F16: 17227541 | I16: 10 | J16: 16221558 | K16: 16467968 | L16: 16717741 | M16: 16970918 | N16: 17227541
A17: 11 | B17: 17025577 | C17: 17310277 | D17: 17599298 | E17: 17892700 | F17: 18190541 | I17: 11 | J17: 17025577 | K17: 17310277 | L17: 17599298 | M17: 17892700 | N17: 18190541
A18: 12 | B18: 17869446 | C18: 18195668 | D18: 18527341 | E18: 18864548 | F18: 19207372 | I18: 12 | J18: 17869446 | K18: 18195668 | L18: 18527341 | M18: 18864548 | N18: 19207372
... A26: 20 | B26: 26313895 | C26: 27119396 | D26: 27948285 | E26: 28801206 | F26: 29678817 | I26: 20 | J26: 26313895 | K26: 27119396 | L26: 27948285 | M26: 28801206 | N26: 29678817
A27: Grand Total | B27: 3.4545666e+08 | C27: 3.5182044e+08 | D27: 3.5831732e+08 | E27: 3.6495018e+08 | F27: 3.7172195e+08 | I27: Grand Total | J27: 3.4545666e+08 | K27: 3.5182044e+08 | L27: 3.5831732e+08 | M27: 3.6495018e+08 | N27: 3.7172195e+08

Sheet WA
A1: ='Return Simulator'!D48 -> 20 | B1: Buy & Hold | K1: =A1 -> 20 | L1: Rebalanced
A5: Year | B5: Custom_ | C5: Traditional (Taxable)_ | D5: Traditional (PPLI)_ | E5: Alternatives Enhanced (Taxable)_ | F5: Alternatives Enhanced (PPLI)_ | K5: Year | L5: Custom_ | M5: Traditional (Taxable)_ | N5: Traditional (PPLI)_ | O5: Alternatives Enhanced (Taxable)_ | P5: Alternatives Enhanced (PPLI)_
A6: {=_xlfn.SEQUENCE(A1,1,1,1)} -> 1 | B6: =IF(A6="","N/A",'1'!V10) -> 10495648 | C6: =IF(A6="","N/A",'2'!V10) -> 10511483 | D6: =IF(A6="","N/A",'3'!V10) -> 10527318 | E6: =IF(A6="","N/A",'4'!V10) -> 10543154 | F6: =IF(A6="","N/A",'5'!V10) -> 10558989 | K6: {=_xlfn.SEQUENCE(K1,1,1,1)} -> 1 | L6: =IF(K6="","N/A",'1'!X10) -> 10495648 | M6: =IF(K6="","N/A",'2'!X10) -> 10511483 | N6: =IF(K6="","N/A",'3'!X10) -> 10527318 | O6: =IF(K6="","N/A",'4'!X10) -> 10543154 | P6: =IF(K6="","N/A",'5'!X10) -> 10558989
A7: 2 | B7: =IF(A7="","N/A",'1'!V11) -> 11017804 | C7: =IF(A7="","N/A",'2'!V11) -> 11051296 | D7: =IF(A7="","N/A",'3'!V11) -> 11084789 | E7: =IF(A7="","N/A",'4'!V11) -> 11118282 | F7: =IF(A7="","N/A",'5'!V11) -> 11151774 | K7: 2 | L7: =IF(K7="","N/A",'1'!X11) -> 11015863 | M7: =IF(K7="","N/A",'2'!X11) -> 11049128 | N7: =IF(K7="","N/A",'3'!X11) -> 11082443 | O7: =IF(K7="","N/A",'4'!X11) -> 11115809 | P7: =IF(K7="","N/A",'5'!X11) -> 11149224
A8: 3 | B8: =IF(A8="","N/A",'1'!V12) -> 11567955 | C8: =IF(A8="","N/A",'2'!V12) -> 11621095 | D8: =IF(A8="","N/A",'3'!V12) -> 11674234 | E8: =IF(A8="","N/A",'4'!V12) -> 11727374 | F8: =IF(A8="","N/A",'5'!V12) -> 11780513 | K8: 3 | L8: =IF(K8="","N/A",'1'!X12) -> 11561862 | M8: =IF(K8="","N/A",'2'!X12) -> 11614272 | N8: =IF(K8="","N/A",'3'!X12) -> 11666841 | O8: =IF(K8="","N/A",'4'!X12) -> 11719568 | P8: =IF(K8="","N/A",'5'!X12) -> 11772454
A9: 4 | B9: =IF(A9="","N/A",'1'!V13) -> 12147677 | C9: =IF(A9="","N/A",'2'!V13) -> 12222634 | D9: =IF(A9="","N/A",'3'!V13) -> 12297591 | E9: =IF(A9="","N/A",'4'!V13) -> 12372548 | F9: =IF(A9="","N/A",'5'!V13) -> 12447506 | K9: 4 | L9: =IF(K9="","N/A",'1'!X13) -> 12134923 | M9: =IF(K9="","N/A",'2'!X13) -> 12208323 | N9: =IF(K9="","N/A",'3'!X13) -> 12282055 | O9: =IF(K9="","N/A",'4'!X13) -> 12356120 | P9: =IF(K9="","N/A",'5'!X13) -> 12430521
A10: 5 | B10: =IF(A10="","N/A",'1'!V14) -> 12758633 | C10: =IF(A10="","N/A",'2'!V14) -> 12857776 | D10: =IF(A10="","N/A",'3'!V14) -> 12956919 | E10: =IF(A10="","N/A",'4'!V14) -> 13056061 | F10: =IF(A10="","N/A",'5'!V14) -> 13155204 | K10: 5 | L10: =IF(K10="","N/A",'1'!X14) -> 12736388 | M10: =IF(K10="","N/A",'2'!X14) -> 12832758 | N10: =IF(K10="","N/A",'3'!X14) -> 12929710 | O10: =IF(K10="","N/A",'4'!X14) -> 13027248 | P10: =IF(K10="","N/A",'5'!X14) -> 13125373
A11: 6 | B11: =IF(A11="","N/A",'1'!V15) -> 13402585 | C11: =IF(A11="","N/A",'2'!V15) -> 13528495 | D11: =IF(A11="","N/A",'3'!V15) -> 13654405 | E11: =IF(A11="","N/A",'4'!V15) -> 13780315 | F11: =IF(A11="","N/A",'5'!V15) -> 13906224 | K11: 6 | L11: =IF(K11="","N/A",'1'!X15) -> 13367665 | M11: =IF(K11="","N/A",'2'!X15) -> 13489132 | N11: =IF(K11="","N/A",'3'!X15) -> 13611518 | O11: =IF(K11="","N/A",'4'!X15) -> 13734827 | P11: =IF(K11="","N/A",'5'!X15) -> 13859066
A12: 7 | B12: =IF(A12="","N/A",'1'!V16) -> 14081397 | C12: =IF(A12="","N/A",'2'!V16) -> 14236887 | D12: =IF(A12="","N/A",'3'!V16) -> 14392376 | E12: =IF(A12="","N/A",'4'!V16) -> 14547866 | F12: =IF(A12="","N/A",'5'!V16) -> 14703355 | K12: 7 | L12: =IF(K12="","N/A",'1'!X16) -> 14030230 | M12: =IF(K12="","N/A",'2'!X16) -> 14179078 | N12: =IF(K12="","N/A",'3'!X16) -> 14329278 | O12: =IF(K12="","N/A",'4'!X16) -> 14480839 | P12: =IF(K12="","N/A",'5'!X16) -> 14633773
A13: 8 | B13: =IF(A13="","N/A",'1'!V17) -> 14797041 | C13: =IF(A13="","N/A",'2'!V17) -> 14985174 | D13: =IF(A13="","N/A",'3'!V17) -> 15173307 | E13: =IF(A13="","N/A",'4'!V17) -> 15361440 | F13: =IF(A13="","N/A",'5'!V17) -> 15549573 | K13: 8 | L13: =IF(K13="","N/A",'1'!X17) -> 14725636 | M13: =IF(K13="","N/A",'2'!X17) -> 14904314 | N13: =IF(K13="","N/A",'3'!X17) -> 15084887 | O13: =IF(K13="","N/A",'4'!X17) -> 15267371 | P13: =IF(K13="","N/A",'5'!X17) -> 15451784
A14: 9 | B14: =IF(A14="","N/A",'1'!V18) -> 15551601 | C14: =IF(A14="","N/A",'2'!V18) -> 15775713 | D14: =IF(A14="","N/A",'3'!V18) -> 15999826 | E14: =IF(A14="","N/A",'4'!V18) -> 16223939 | F14: =IF(A14="","N/A",'5'!V18) -> 16448051 | K14: 9 | L14: =IF(K14="","N/A",'1'!X18) -> 15455509 | M14: =IF(K14="","N/A",'2'!X18) -> 15666645 | N14: =IF(K14="","N/A",'3'!X18) -> 15880341 | O14: =IF(K14="","N/A",'4'!X18) -> 16096624 | P14: =IF(K14="","N/A",'5'!X18) -> 16315522
A15: 10 | B15: =IF(A15="","N/A",'1'!V19) -> 16347284 | C15: =IF(A15="","N/A",'2'!V19) -> 16611007 | D15: =IF(A15="","N/A",'3'!V19) -> 16874731 | E15: =IF(A15="","N/A",'4'!V19) -> 17138454 | F15: =IF(A15="","N/A",'5'!V19) -> 17402177 | K15: 10 | L15: =IF(K15="","N/A",'1'!X19) -> 16221558 | M15: =IF(K15="","N/A",'2'!X19) -> 16467968 | N15: =IF(K15="","N/A",'3'!X19) -> 16717741 | O15: =IF(K15="","N/A",'4'!X19) -> 16970918 | P15: =IF(K15="","N/A",'5'!X19) -> 17227541
A16: 11 | B16: =IF(A16="","N/A",'1'!V20) -> 17186426 | C16: =IF(A16="","N/A",'2'!V20) -> 17493711 | D16: =IF(A16="","N/A",'3'!V20) -> 17800995 | E16: =IF(A16="","N/A",'4'!V20) -> 18108279 | F16: =IF(A16="","N/A",'5'!V20) -> 18415564 | K16: 11 | L16: =IF(K16="","N/A",'1'!X20) -> 17025577 | M16: =IF(K16="","N/A",'2'!X20) -> 17310277 | N16: =IF(K16="","N/A",'3'!X20) -> 17599298 | O16: =IF(K16="","N/A",'4'!X20) -> 17892700 | P16: =IF(K16="","N/A",'5'!X20) -> 18190541
A17: 12 | B17: =IF(A17="","N/A",'1'!V21) -> 18071498 | C17: =IF(A17="","N/A",'2'!V21) -> 18426640 | D17: =IF(A17="","N/A",'3'!V21) -> 18781782 | E17: =IF(A17="","N/A",'4'!V21) -> 19136925 | F17: =IF(A17="","N/A",'5'!V21) -> 19492067 | K17: 12 | L17: =IF(K17="","N/A",'1'!X21) -> 17869446 | M17: =IF(K17="","N/A",'2'!X21) -> 18195668 | N17: =IF(K17="","N/A",'3'!X21) -> 18527341 | O17: =IF(K17="","N/A",'4'!X21) -> 18864548 | P17: =IF(K17="","N/A",'5'!X21) -> 19207372
A18: 13 | B18: =IF(A18="","N/A",'1'!V22) -> 19005113 | C18: =IF(A18="","N/A",'2'!V22) -> 19412785 | D18: =IF(A18="","N/A",'3'!V22) -> 19820458 | E18: =IF(A18="","N/A",'4'!V22) -> 20228130 | F18: =IF(A18="","N/A",'5'!V22) -> 20635802 | K18: 13 | L18: =IF(K18="","N/A",'1'!X22) -> 18755141 | M18: =IF(K18="","N/A",'2'!X22) -> 19126346 | N18: =IF(K18="","N/A",'3'!X22) -> 19504322 | O18: =IF(K18="","N/A",'4'!X22) -> 19889183 | P18: =IF(K18="","N/A",'5'!X22) -> 20281043
... A25: 20 | B25: =IF(A25="","N/A",'1'!V29) -> 27153622 | C25: =IF(A25="","N/A",'2'!V29) -> 28098547 | D25: =IF(A25="","N/A",'3'!V29) -> 29043472 | E25: =IF(A25="","N/A",'4'!V29) -> 29988397 | F25: =IF(A25="","N/A",'5'!V29) -> 30933322 | K25: 20 | L25: =IF(K25="","N/A",'1'!X29) -> 26313895 | M25: =IF(K25="","N/A",'2'!X29) -> 27119396 | N25: =IF(K25="","N/A",'3'!X29) -> 27948285 | O25: =IF(K25="","N/A",'4'!X29) -> 28801206 | P25: =IF(K25="","N/A",'5'!X29) -> 29678817
B26: =IF(A26="","N/A",'1'!V30) -> N/A | C26: =IF(A26="","N/A",'2'!V30) -> N/A | D26: =IF(A26="","N/A",'3'!V30) -> N/A | E26: =IF(A26="","N/A",'4'!V30) -> N/A | F26: =IF(A26="","N/A",'5'!V30) -> N/A | L26: =IF(K26="","N/A",'1'!X30) -> N/A | M26: =IF(K26="","N/A",'2'!X30) -> N/A | N26: =IF(K26="","N/A",'3'!X30) -> N/A | O26: =IF(K26="","N/A",'4'!X30) -> N/A | P26: =IF(K26="","N/A",'5'!X30) -> N/A
B27: =IF(A27="","N/A",'1'!V31) -> N/A | C27: =IF(A27="","N/A",'2'!V31) -> N/A | D27: =IF(A27="","N/A",'3'!V31) -> N/A | E27: =IF(A27="","N/A",'4'!V31) -> N/A | F27: =IF(A27="","N/A",'5'!V31) -> N/A | L27: =IF(K27="","N/A",'1'!X31) -> N/A | M27: =IF(K27="","N/A",'2'!X31) -> N/A | N27: =IF(K27="","N/A",'3'!X31) -> N/A | O27: =IF(K27="","N/A",'4'!X31) -> N/A | P27: =IF(K27="","N/A",'5'!X31) -> N/A
B28: =IF(A28="","N/A",'1'!V32) -> N/A | C28: =IF(A28="","N/A",'2'!V32) -> N/A | D28: =IF(A28="","N/A",'3'!V32) -> N/A | E28: =IF(A28="","N/A",'4'!V32) -> N/A | F28: =IF(A28="","N/A",'5'!V32) -> N/A | L28: =IF(K28="","N/A",'1'!X32) -> N/A | M28: =IF(K28="","N/A",'2'!X32) -> N/A | N28: =IF(K28="","N/A",'3'!X32) -> N/A | O28: =IF(K28="","N/A",'4'!X32) -> N/A | P28: =IF(K28="","N/A",'5'!X32) -> N/A
B29: =IF(A29="","N/A",'1'!V33) -> N/A | C29: =IF(A29="","N/A",'2'!V33) -> N/A | D29: =IF(A29="","N/A",'3'!V33) -> N/A | E29: =IF(A29="","N/A",'4'!V33) -> N/A | F29: =IF(A29="","N/A",'5'!V33) -> N/A | L29: =IF(K29="","N/A",'1'!X33) -> N/A | M29: =IF(K29="","N/A",'2'!X33) -> N/A | N29: =IF(K29="","N/A",'3'!X33) -> N/A | O29: =IF(K29="","N/A",'4'!X33) -> N/A | P29: =IF(K29="","N/A",'5'!X33) -> N/A
B30: =IF(A30="","N/A",'1'!V34) -> N/A | C30: =IF(A30="","N/A",'2'!V34) -> N/A | D30: =IF(A30="","N/A",'3'!V34) -> N/A | E30: =IF(A30="","N/A",'4'!V34) -> N/A | F30: =IF(A30="","N/A",'5'!V34) -> N/A | L30: =IF(K30="","N/A",'1'!X34) -> N/A | M30: =IF(K30="","N/A",'2'!X34) -> N/A | N30: =IF(K30="","N/A",'3'!X34) -> N/A | O30: =IF(K30="","N/A",'4'!X34) -> N/A | P30: =IF(K30="","N/A",'5'!X34) -> N/A
B31: =IF(A31="","N/A",'1'!V35) -> N/A | C31: =IF(A31="","N/A",'2'!V35) -> N/A | D31: =IF(A31="","N/A",'3'!V35) -> N/A | E31: =IF(A31="","N/A",'4'!V35) -> N/A | F31: =IF(A31="","N/A",'5'!V35) -> N/A | L31: =IF(K31="","N/A",'1'!X35) -> N/A | M31: =IF(K31="","N/A",'2'!X35) -> N/A | N31: =IF(K31="","N/A",'3'!X35) -> N/A | O31: =IF(K31="","N/A",'4'!X35) -> N/A | P31: =IF(K31="","N/A",'5'!X35) -> N/A
B32: =IF(A32="","N/A",'1'!V36) -> N/A | C32: =IF(A32="","N/A",'2'!V36) -> N/A | D32: =IF(A32="","N/A",'3'!V36) -> N/A | E32: =IF(A32="","N/A",'4'!V36) -> N/A | F32: =IF(A32="","N/A",'5'!V36) -> N/A | L32: =IF(K32="","N/A",'1'!X36) -> N/A | M32: =IF(K32="","N/A",'2'!X36) -> N/A | N32: =IF(K32="","N/A",'3'!X36) -> N/A | O32: =IF(K32="","N/A",'4'!X36) -> N/A | P32: =IF(K32="","N/A",'5'!X36) -> N/A
B33: =IF(A33="","N/A",'1'!V37) -> N/A | C33: =IF(A33="","N/A",'2'!V37) -> N/A | D33: =IF(A33="","N/A",'3'!V37) -> N/A | E33: =IF(A33="","N/A",'4'!V37) -> N/A | F33: =IF(A33="","N/A",'5'!V37) -> N/A | L33: =IF(K33="","N/A",'1'!X37) -> N/A | M33: =IF(K33="","N/A",'2'!X37) -> N/A | N33: =IF(K33="","N/A",'3'!X37) -> N/A | O33: =IF(K33="","N/A",'4'!X37) -> N/A | P33: =IF(K33="","N/A",'5'!X37) -> N/A
B34: =IF(A34="","N/A",'1'!V38) -> N/A | C34: =IF(A34="","N/A",'2'!V38) -> N/A | D34: =IF(A34="","N/A",'3'!V38) -> N/A | E34: =IF(A34="","N/A",'4'!V38) -> N/A | F34: =IF(A34="","N/A",'5'!V38) -> N/A | L34: =IF(K34="","N/A",'1'!X38) -> N/A | M34: =IF(K34="","N/A",'2'!X38) -> N/A | N34: =IF(K34="","N/A",'3'!X38) -> N/A | O34: =IF(K34="","N/A",'4'!X38) -> N/A | P34: =IF(K34="","N/A",'5'!X38) -> N/A
B35: =IF(A35="","N/A",'1'!V39) -> N/A | C35: =IF(A35="","N/A",'2'!V39) -> N/A | D35: =IF(A35="","N/A",'3'!V39) -> N/A | E35: =IF(A35="","N/A",'4'!V39) -> N/A | F35: =IF(A35="","N/A",'5'!V39) -> N/A | L35: =IF(K35="","N/A",'1'!X39) -> N/A | M35: =IF(K35="","N/A",'2'!X39) -> N/A | N35: =IF(K35="","N/A",'3'!X39) -> N/A | O35: =IF(K35="","N/A",'4'!X39) -> N/A | P35: =IF(K35="","N/A",'5'!X39) -> N/A
B36: =IF(A36="","N/A",'1'!V40) -> N/A | C36: =IF(A36="","N/A",'2'!V40) -> N/A | D36: =IF(A36="","N/A",'3'!V40) -> N/A | E36: =IF(A36="","N/A",'4'!V40) -> N/A | F36: =IF(A36="","N/A",'5'!V40) -> N/A | L36: =IF(K36="","N/A",'1'!X40) -> N/A | M36: =IF(K36="","N/A",'2'!X40) -> N/A | N36: =IF(K36="","N/A",'3'!X40) -> N/A | O36: =IF(K36="","N/A",'4'!X40) -> N/A | P36: =IF(K36="","N/A",'5'!X40) -> N/A
B37: =IF(A37="","N/A",'1'!V41) -> N/A | C37: =IF(A37="","N/A",'2'!V41) -> N/A | D37: =IF(A37="","N/A",'3'!V41) -> N/A | E37: =IF(A37="","N/A",'4'!V41) -> N/A | F37: =IF(A37="","N/A",'5'!V41) -> N/A | L37: =IF(K37="","N/A",'1'!X41) -> N/A | M37: =IF(K37="","N/A",'2'!X41) -> N/A | N37: =IF(K37="","N/A",'3'!X41) -> N/A | O37: =IF(K37="","N/A",'4'!X41) -> N/A | P37: =IF(K37="","N/A",'5'!X41) -> N/A
... B105: =IF(A105="","N/A",'1'!V109) -> N/A | C105: =IF(A105="","N/A",'2'!V109) -> N/A | D105: =IF(A105="","N/A",'3'!V109) -> N/A | E105: =IF(A105="","N/A",'4'!V109) -> N/A | F105: =IF(A105="","N/A",'5'!V109) -> N/A | L105: =IF(K105="","N/A",'1'!X109) -> N/A | M105: =IF(K105="","N/A",'2'!X109) -> N/A | N105: =IF(K105="","N/A",'3'!X109) -> N/A | O105: =IF(K105="","N/A",'4'!X109) -> N/A | P105: =IF(K105="","N/A",'5'!X109) -> N/A

Sheet Rank
A1: Buy & Hold
A2: ='Return Simulator'!D48 -> 20 | C2: ='Return Simulator'!C4 -> Current Client Portfolio | D2: ='Return Simulator'!D5 -> 27153622 | E2: ='Return Simulator'!D6 -> 0.05121461 | F2: =_xlfn.RANK.EQ(D2,$D$2:$D$6,0) -> 5 | G2: =_xlfn.XLOOKUP(F2,$O$2:$O$6,$P$2:$P$6) -> 5th | I2: {=_xlfn._xlws.SORT(C2:G6,2,-1)} -> 40% of Current Portfolio inside PPLI | J2: 30933322 | K2: 0.058086877 | L2: 1 | M2: 1st | O2: 1 | P2: 1st
C3: ='Return Simulator'!C10 -> 10% of Current Portfolio inside PPLI | D3: ='Return Simulator'!D11 -> 28098547 | E3: ='Return Simulator'!D12 -> 0.053014116 | F3: =_xlfn.RANK.EQ(D3,$D$2:$D$6,0) -> 4 | G3: =_xlfn.XLOOKUP(F3,$O$2:$O$6,$P$2:$P$6) -> 4th | I3: 30% of Current Portfolio inside PPLI | J3: 29988397 | K3: 0.056446875 | L3: 2 | M3: 2nd | O3: 2 | P3: 2nd
C4: ='Return Simulator'!C14 -> 20% of Current Portfolio inside PPLI | D4: ='Return Simulator'!D15 -> 29043472 | E4: ='Return Simulator'!D16 -> 0.054757025 | F4: =_xlfn.RANK.EQ(D4,$D$2:$D$6,0) -> 3 | G4: =_xlfn.XLOOKUP(F4,$O$2:$O$6,$P$2:$P$6) -> 3rd | I4: 20% of Current Portfolio inside PPLI | J4: 29043472 | K4: 0.054757025 | L4: 3 | M4: 3rd | O4: 3 | P4: 3rd
C5: ='Return Simulator'!C18 -> 30% of Current Portfolio inside PPLI | D5: ='Return Simulator'!D19 -> 29988397 | E5: ='Return Simulator'!D20 -> 0.056446875 | F5: =_xlfn.RANK.EQ(D5,$D$2:$D$6,0) -> 2 | G5: =_xlfn.XLOOKUP(F5,$O$2:$O$6,$P$2:$P$6) -> 2nd | I5: 10% of Current Portfolio inside PPLI | J5: 28098547 | K5: 0.053014116 | L5: 4 | M5: 4th | O5: 4 | P5: 4th
C6: ='Return Simulator'!C22 -> 40% of Current Portfolio inside PPLI | D6: ='Return Simulator'!D23 -> 30933322 | E6: ='Return Simulator'!D24 -> 0.058086877 | F6: =_xlfn.RANK.EQ(D6,$D$2:$D$6,0) -> 1 | G6: =_xlfn.XLOOKUP(F6,$O$2:$O$6,$P$2:$P$6) -> 1st | I6: Current Client Portfolio | J6: 27153622 | K6: 0.05121461 | L6: 5 | M6: 5th | O6: 5 | P6: 5th
A9: Rebalanced
A10: =A2 -> 20 | C10: =C2 -> Current Client Portfolio | D10: ='Return Simulator'!X49 -> 26313895 | E10: ='Return Simulator'!X58 -> 0.0495648 | F10: =_xlfn.RANK.EQ(D10,$D$10:$D$14,0) -> 5 | G10: =_xlfn.XLOOKUP(F10,$O$2:$O$6,$P$2:$P$6) -> 5th | I10: {=_xlfn._xlws.SORT(C10:G14,2,-1)} -> 40% of Current Portfolio inside PPLI | J10: 29678817 | K10: 0.05589888 | L10: 1 | M10: 1st | O10: 1 | P10: 1st
C11: =C3 -> 10% of Current Portfolio inside PPLI | D11: ='Return Simulator'!AA49 -> 27119396 | E11: ='Return Simulator'!AA58 -> 0.05114832 | F11: =_xlfn.RANK.EQ(D11,$D$10:$D$14,0) -> 4 | G11: =_xlfn.XLOOKUP(F11,$O$2:$O$6,$P$2:$P$6) -> 4th | I11: 30% of Current Portfolio inside PPLI | J11: 28801206 | K11: 0.05431536 | L11: 2 | M11: 2nd | O11: 2 | P11: 2nd
C12: =C4 -> 20% of Current Portfolio inside PPLI | D12: ='Return Simulator'!AD49 -> 27948285 | E12: ='Return Simulator'!AD58 -> 0.05273184 | F12: =_xlfn.RANK.EQ(D12,$D$10:$D$14,0) -> 3 | G12: =_xlfn.XLOOKUP(F12,$O$2:$O$6,$P$2:$P$6) -> 3rd | I12: 20% of Current Portfolio inside PPLI | J12: 27948285 | K12: 0.05273184 | L12: 3 | M12: 3rd | O12: 3 | P12: 3rd
C13: =C5 -> 30% of Current Portfolio inside PPLI | D13: ='Return Simulator'!AG49 -> 28801206 | E13: ='Return Simulator'!AG58 -> 0.05431536 | F13: =_xlfn.RANK.EQ(D13,$D$10:$D$14,0) -> 2 | G13: =_xlfn.XLOOKUP(F13,$O$2:$O$6,$P$2:$P$6) -> 2nd | I13: 10% of Current Portfolio inside PPLI | J13: 27119396 | K13: 0.05114832 | L13: 4 | M13: 4th | O13: 4 | P13: 4th
C14: =C6 -> 40% of Current Portfolio inside PPLI | D14: ='Return Simulator'!AJ49 -> 29678817 | E14: ='Return Simulator'!AJ58 -> 0.05589888 | F14: =_xlfn.RANK.EQ(D14,$D$10:$D$14,0) -> 1 | G14: =_xlfn.XLOOKUP(F14,$O$2:$O$6,$P$2:$P$6) -> 1st | I14: Current Client Portfolio | J14: 26313895 | K14: 0.0495648 | L14: 5 | M14: 5th | O14: 5 | P14: 5th

Sheet Strategy Feeder >

Sheet 1
B2: Initial Capital ($) | C2: ='Return Simulator'!D47 -> 10000000 | I2: Stocks (Taxable) | J2: Stocks (Taxable) | K2: Stocks (PPLI) | L2: Stocks (PPLI) | M2: Bonds (Taxable) | N2: Bonds (Taxable) | O2: Bonds (PPLI) | P2: Bonds (PPLI) | Q2: Alternatives (Taxable) | R2: Alternatives (Taxable) | S2: Alternatives (PPLI) | T2: Alternatives (PPLI) | W2: Weighted Average | X2: Weighted Average
B3: Time Horizon (Years) | C3: ='Return Simulator'!D48 -> 20 | H3: Weight | I3: =$D$7*(1-$E$7) -> 0.48 | J3: =$D$7*(1-$E$7) -> 0.48 | K3: =$D$7*$E$7 -> 0 | L3: =$D$7*$E$7 -> 0 | M3: =$D$8*(1-$E$8) -> 0.32 | N3: =$D$8*(1-$E$8) -> 0.32 | O3: =$D$8*$E$8 -> 0 | P3: =$D$8*$E$8 -> 0 | Q3: =$D$9*(1-$E$9) -> 0.2 | R3: =$D$9*(1-$E$9) -> 0.2 | S3: =$D$9*$E$9 -> 0 | T3: =$D$9*$E$9 -> 0 | W3: =SUM(I3,K3,M3,O3,Q3,S3) -> 1 | X3: =SUM(J3,L3,N3,P3,R3,T3) -> 1
H4: Return | I4: =$C$7 -> 0.08 | J4: =$C$7 -> 0.08 | K4: =$C$7 -> 0.08 | L4: =$C$7 -> 0.08 | M4: =$C$8 -> 0.05 | N4: =$C$8 -> 0.05 | O4: =$C$8 -> 0.05 | P4: =$C$8 -> 0.05 | Q4: =$C$9 -> 0.08 | R4: =$C$9 -> 0.08 | S4: =$C$9 -> 0.08 | T4: =$C$9 -> 0.08 | W4: =SUMPRODUCT(I3:T3,I4:T4)/2 -> 0.0704 | X4: =SUMPRODUCT(I3:T3,I4:T4)/2 -> 0.0704
D5: =IF(SUM(D7:D9)<>1,"Error","Good") -> Good | H5: Drag | I5: 0 | J5: =$C$7*($C$15+$C$16) -> 0.01904 | K5: 0 | L5: =$C$11 -> 0.005 | M5: 0 | N5: =$C$8*($C$14+$C$16) -> 0.0204 | O5: 0 | P5: =$C$11 -> 0.005 | Q5: 0 | R5: =(50%*$C$9*($C$14+$C$16))+(50%*$C$9*($C$15+$C$16)) -> 0.02584 | S5: 0 | T5: =$C$11 -> 0.005 | W5: 0 | X5: =SUMPRODUCT(J3:T3,J5:T5) -> 0.0208352
C6: Returns | D6: Weight | E6: PPLI Allocation
B7: Stocks | C7: ='Return Simulator'!D56 -> 0.08 | D7: ='Return Simulator'!D51 -> 0.48 | E7: ='Return Simulator'!D66 -> 0 | U7: Buy & Hold | V7: Buy & Hold | W7: Rebalanced | X7: Rebalanced | Y7: Buy & Hold | Z7: Buy & Hold | AA7: Buy & Hold | AB7: Rebalanced | AC7: Rebalanced | AD7: Rebalanced | AE7: Buy & Hold | AF7: Buy & Hold | AG7: Buy & Hold | AH7: Rebalanced | AI7: Rebalanced | AJ7: Rebalanced | AK7: Buy & Hold | AL7: Buy & Hold | AM7: Buy & Hold | AN7: Rebalanced | AO7: Rebalanced | AP7: Rebalanced
B8: Bonds | C8: ='Return Simulator'!D57 -> 0.05 | D8: ='Return Simulator'!D52 -> 0.32 | E8: ='Return Simulator'!D67 -> 0 | I8: Gross | J8: Net | K8: Gross | L8: Net | M8: Gross | N8: Net | O8: Gross | P8: Net | Q8: Gross | R8: Net | S8: Gross | T8: Net | U8: Gross | V8: Net | W8: Gross | X8: Net | Y8: Gross | Z8: Net | AB8: Gross | AC8: Net | AE8: Gross | AF8: Net | AH8: Gross | AI8: Net | AK8: Gross | AL8: Net | AN8: Gross | AO8: Net
B9: Alternatives | C9: ='Return Simulator'!D58 -> 0.08 | D9: ='Return Simulator'!D53 -> 0.2 | E9: ='Return Simulator'!D68 -> 0 | G9: Year | H9: Contributions | I9: Stocks (Taxable) | J9: Stocks (Taxable) | K9: Stocks (PPLI) | L9: Stocks (PPLI) | M9: Bonds (Taxable) | N9: Bonds (Taxable) | O9: Bonds (PPLI) | P9: Bonds (PPLI) | Q9: Alternatives (Taxable) | R9: Alternatives (Taxable) | S9: Alternatives (PPLI) | T9: Alternatives (PPLI) | U9: Total | V9: Total | W9: Total | X9: Total | Y9: Period Return | Z9: Period Return | AA9: Period Drag | AB9: Period Return | AC9: Period Return | AD9: Period Drag | AE9: Total Return | AF9: Total Return | AG9: Total Drag | AH9: Total Return | AI9: Total Return | AJ9: Total Drag | AK9: Total Return (Annualized) | AL9: Total Return (Annualized) | AM9: Annaulized Drag | AN9: Total Return (Annualized) | AO9: Total Return (Annualized) | AP9: Annaulized Drag
G10: {=_xlfn.SEQUENCE(C3,1,1,1)} -> 1 | H10: =IF(G10="","",SUMIFS(Add_Contributions[[#All],[Amount ($)]],Add_Contributions[[#All],[Year]],G10)) -> 0 | I10: =IF($G10="","",IF($G10=1,(($C$2+$H10)*I$3)*(1+(I$4-I$5)),((I9+($H10*I$3))*(1+(I$4-I$5))))) -> 5184000 | J10: =IF($G10="","",IF($G10=1,(($C$2+$H10)*J$3)*(1+(J$4-J$5)),((J9+($H10*J$3))*(1+(J$4-J$5))))) -> 5092608 | K10: =IF($G10="","",IF($G10=1,(($C$2+$H10)*K$3)*(1+(K$4-K$5)),((K9+($H10*K$3))*(1+(K$4-K$5))))) -> 0 | L10: =IF($G10="","",IF($G10=1,(($C$2+$H10)*L$3)*(1+(L$4-L$5)),((L9+($H10*L$3))*(1+(L$4-L$5))))) -> 0 | M10: =IF($G10="","",IF($G10=1,(($C$2+$H10)*M$3)*(1+(M$4-M$5)),((M9+($H10*M$3))*(1+(M$4-M$5))))) -> 3360000 | N10: =IF($G10="","",IF($G10=1,(($C$2+$H10)*N$3)*(1+(N$4-N$5)),((N9+($H10*N$3))*(1+(N$4-N$5))))) -> 3294720 | O10: =IF($G10="","",IF($G10=1,(($C$2+$H10)*O$3)*(1+(O$4-O$5)),((O9+($H10*O$3))*(1+(O$4-O$5))))) -> 0 | P10: =IF($G10="","",IF($G10=1,(($C$2+$H10)*P$3)*(1+(P$4-P$5)),((P9+($H10*P$3))*(1+(P$4-P$5))))) -> 0 | ... T10: =IF($G10="","",IF($G10=1,(($C$2+$H10)*T$3)*(1+(T$4-T$5)),((T9+($H10*T$3))*(1+(T$4-T$5))))) -> 0 | U10: =IF(G10="","",SUM(I10,K10,M10,O10,Q10,S10)) -> 10704000 | V10: =IF(H10="","",SUM(J10,L10,N10,P10,R10,T10)) -> 10495648 | W10: =IF($G10="","",IF($G10=1,(($C$2+$H10)*W$3)*(1+(W$4-W$5)),((W9+($H10*W$3))*(1+(W$4-W$5))))) -> 10704000 | X10: =IF($G10="","",IF($G10=1,(($C$2+$H10)*X$3)*(1+(X$4-X$5)),((X9+($H10*X$3))*(1+(X$4-X$5))))) -> 10495648 | Y10: =IF($G10="","",IF($G10=1,(U10-$C$2-H10)/($C$2+H10),(U10-U9-H10)/(U9+H10))) -> 0.0704 | Z10: =IF($G10="","",IF($G10=1,(V10-$C$2-H10)/($C$2+H10),(V10-V9-H10)/(V9+H10))) -> 0.0495648 | AA10: =IF($G10="","",Z10-Y10) -> -0.0208352 | AB10: =IF($G10="","",IF($G10=1,(W10-$C$2-H10)/($C$2+H10),(W10-W9-H10)/(W9+H10))) -> 0.0704 | AC10: =IF($G10="","",IF($G10=1,(X10-$C$2-H10)/($C$2+H10),(X10-X9-H10)/(X9+H10))) -> 0.0495648 | AD10: =IF($G10="","",AC10-AB10) -> -0.0208352 | AE10: =IF($G10="","",IF($G10=1,Y10,(1+Y10)*(1+AE9)-1)) -> 0.0704 | AF10: =IF($G10="","",IF($G10=1,Z10,(1+Z10)*(1+AF9)-1)) -> 0.0495648 | AG10: =IF($G10="","",AF10-AE10) -> -0.0208352 | AH10: =IF($G10="","",IF($G10=1,AB10,(1+AB10)*(1+AH9)-1)) -> 0.0704 | AI10: =IF($G10="","",IF($G10=1,AC10,(1+AC10)*(1+AI9)-1)) -> 0.0495648 | AJ10: =IF($G10="","",AI10-AH10) -> -0.0208352 | AK10: =IF($G10="","",(1+AE10)^(1/G10)-1) -> 0.0704 | AL10: =IF($G10="","",(1+AF10)^(1/G10)-1) -> 0.0495648 | AM10: =IF($G10="","",AL10-AK10) -> -0.0208352 | AN10: =IF($G10="","",(1+AH10)^(1/G10)-1) -> 0.0704 | AO10: =IF($G10="","",(1+AI10)^(1/G10)-1) -> 0.0495648 | AP10: =IF($G10="","",AO10-AN10) -> -0.0208352
B11: PPLI Policy Costs | C11: ='Return Simulator'!D71 -> 0.005 | G11: 2 | H11: =IF(G11="","",SUMIFS(Add_Contributions[[#All],[Amount ($)]],Add_Contributions[[#All],[Year]],G11)) -> 0 | I11: =IF($G11="","",IF($G11=1,(($C$2+$H11)*I$3)*(1+(I$4-I$5)),((I10+($H11*I$3))*(1+(I$4-I$5))))) -> 5598720 | J11: =IF($G11="","",IF($G11=1,(($C$2+$H11)*J$3)*(1+(J$4-J$5)),((J10+($H11*J$3))*(1+(J$4-J$5))))) -> 5403053.4 | K11: =IF($G11="","",IF($G11=1,(($C$2+$H11)*K$3)*(1+(K$4-K$5)),((K10+($H11*K$3))*(1+(K$4-K$5))))) -> 0 | L11: =IF($G11="","",IF($G11=1,(($C$2+$H11)*L$3)*(1+(L$4-L$5)),((L10+($H11*L$3))*(1+(L$4-L$5))))) -> 0 | M11: =IF($G11="","",IF($G11=1,(($C$2+$H11)*M$3)*(1+(M$4-M$5)),((M10+($H11*M$3))*(1+(M$4-M$5))))) -> 3528000 | N11: =IF($G11="","",IF($G11=1,(($C$2+$H11)*N$3)*(1+(N$4-N$5)),((N10+($H11*N$3))*(1+(N$4-N$5))))) -> 3392243.7 | O11: =IF($G11="","",IF($G11=1,(($C$2+$H11)*O$3)*(1+(O$4-O$5)),((O10+($H11*O$3))*(1+(O$4-O$5))))) -> 0 | P11: =IF($G11="","",IF($G11=1,(($C$2+$H11)*P$3)*(1+(P$4-P$5)),((P10+($H11*P$3))*(1+(P$4-P$5))))) -> 0 | ... T11: =IF($G11="","",IF($G11=1,(($C$2+$H11)*T$3)*(1+(T$4-T$5)),((T10+($H11*T$3))*(1+(T$4-T$5))))) -> 0 | U11: =IF(G11="","",SUM(I11,K11,M11,O11,Q11,S11)) -> 11459520 | V11: =IF(H11="","",SUM(J11,L11,N11,P11,R11,T11)) -> 11017804 | W11: =IF($G11="","",IF($G11=1,(($C$2+$H11)*W$3)*(1+(W$4-W$5)),((W10+($H11*W$3))*(1+(W$4-W$5))))) -> 11457562 | X11: =IF($G11="","",IF($G11=1,(($C$2+$H11)*X$3)*(1+(X$4-X$5)),((X10+($H11*X$3))*(1+(X$4-X$5))))) -> 11015863 | Y11: =IF($G11="","",IF($G11=1,(U11-$C$2-H11)/($C$2+H11),(U11-U10-H11)/(U10+H11))) -> 0.07058296 | Z11: =IF($G11="","",IF($G11=1,(V11-$C$2-H11)/($C$2+H11),(V11-V10-H11)/(V10+H11))) -> 0.049749735 | AA11: =IF($G11="","",Z11-Y11) -> -0.020833225 | AB11: =IF($G11="","",IF($G11=1,(W11-$C$2-H11)/($C$2+H11),(W11-W10-H11)/(W10+H11))) -> 0.0704 | AC11: =IF($G11="","",IF($G11=1,(X11-$C$2-H11)/($C$2+H11),(X11-X10-H11)/(X10+H11))) -> 0.0495648 | AD11: =IF($G11="","",AC11-AB11) -> -0.0208352 | AE11: =IF($G11="","",IF($G11=1,Y11,(1+Y11)*(1+AE10)-1)) -> 0.145952 | AF11: =IF($G11="","",IF($G11=1,Z11,(1+Z11)*(1+AF10)-1)) -> 0.10178037 | AG11: =IF($G11="","",AF11-AE11) -> -0.044171629 | AH11: =IF($G11="","",IF($G11=1,AB11,(1+AB11)*(1+AH10)-1)) -> 0.14575616 | AI11: =IF($G11="","",IF($G11=1,AC11,(1+AC11)*(1+AI10)-1)) -> 0.10158627 | AJ11: =IF($G11="","",AI11-AH11) -> -0.044169891 | AK11: =IF($G11="","",(1+AE11)^(1/G11)-1) -> 0.070491476 | AL11: =IF($G11="","",(1+AF11)^(1/G11)-1) -> 0.049657263 | AM11: =IF($G11="","",AL11-AK11) -> -0.020834212 | AN11: =IF($G11="","",(1+AH11)^(1/G11)-1) -> 0.0704 | AO11: =IF($G11="","",(1+AI11)^(1/G11)-1) -> 0.0495648 | AP11: =IF($G11="","",AO11-AN11) -> -0.0208352
B12: PPLI Start Up Costs | G12: 3 | H12: =IF(G12="","",SUMIFS(Add_Contributions[[#All],[Amount ($)]],Add_Contributions[[#All],[Year]],G12)) -> 0 | I12: =IF($G12="","",IF($G12=1,(($C$2+$H12)*I$3)*(1+(I$4-I$5)),((I11+($H12*I$3))*(1+(I$4-I$5))))) -> 6046617.6 | J12: =IF($G12="","",IF($G12=1,(($C$2+$H12)*J$3)*(1+(J$4-J$5)),((J11+($H12*J$3))*(1+(J$4-J$5))))) -> 5732423.5 | K12: =IF($G12="","",IF($G12=1,(($C$2+$H12)*K$3)*(1+(K$4-K$5)),((K11+($H12*K$3))*(1+(K$4-K$5))))) -> 0 | L12: =IF($G12="","",IF($G12=1,(($C$2+$H12)*L$3)*(1+(L$4-L$5)),((L11+($H12*L$3))*(1+(L$4-L$5))))) -> 0 | M12: =IF($G12="","",IF($G12=1,(($C$2+$H12)*M$3)*(1+(M$4-M$5)),((M11+($H12*M$3))*(1+(M$4-M$5))))) -> 3704400 | N12: =IF($G12="","",IF($G12=1,(($C$2+$H12)*N$3)*(1+(N$4-N$5)),((N11+($H12*N$3))*(1+(N$4-N$5))))) -> 3492654.1 | O12: =IF($G12="","",IF($G12=1,(($C$2+$H12)*O$3)*(1+(O$4-O$5)),((O11+($H12*O$3))*(1+(O$4-O$5))))) -> 0 | P12: =IF($G12="","",IF($G12=1,(($C$2+$H12)*P$3)*(1+(P$4-P$5)),((P11+($H12*P$3))*(1+(P$4-P$5))))) -> 0 | ... T12: =IF($G12="","",IF($G12=1,(($C$2+$H12)*T$3)*(1+(T$4-T$5)),((T11+($H12*T$3))*(1+(T$4-T$5))))) -> 0 | U12: =IF(G12="","",SUM(I12,K12,M12,O12,Q12,S12)) -> 12270442 | V12: =IF(H12="","",SUM(J12,L12,N12,P12,R12,T12)) -> 11567955 | W12: =IF($G12="","",IF($G12=1,(($C$2+$H12)*W$3)*(1+(W$4-W$5)),((W11+($H12*W$3))*(1+(W$4-W$5))))) -> 12264174 | X12: =IF($G12="","",IF($G12=1,(($C$2+$H12)*X$3)*(1+(X$4-X$5)),((X11+($H12*X$3))*(1+(X$4-X$5))))) -> 11561862 | Y12: =IF($G12="","",IF($G12=1,(U12-$C$2-H12)/($C$2+H12),(U12-U11-H12)/(U11+H12))) -> 0.070764011 | Z12: =IF($G12="","",IF($G12=1,(V12-$C$2-H12)/($C$2+H12),(V12-V11-H12)/(V11+H12))) -> 0.049932956 | AA12: =IF($G12="","",Z12-Y12) -> -0.020831055 | AB12: =IF($G12="","",IF($G12=1,(W12-$C$2-H12)/($C$2+H12),(W12-W11-H12)/(W11+H12))) -> 0.0704 | AC12: =IF($G12="","",IF($G12=1,(X12-$C$2-H12)/($C$2+H12),(X12-X11-H12)/(X11+H12))) -> 0.0495648 | AD12: =IF($G12="","",AC12-AB12) -> -0.0208352 | AE12: =IF($G12="","",IF($G12=1,Y12,(1+Y12)*(1+AE11)-1)) -> 0.22704416 | AF12: =IF($G12="","",IF($G12=1,Z12,(1+Z12)*(1+AF11)-1)) -> 0.15679552 | AG12: =IF($G12="","",AF12-AE12) -> -0.070248639 | AH12: =IF($G12="","",IF($G12=1,AB12,(1+AB12)*(1+AH11)-1)) -> 0.22641739 | AI12: =IF($G12="","",IF($G12=1,AC12,(1+AC12)*(1+AI11)-1)) -> 0.15618617 | AJ12: =IF($G12="","",AI12-AH12) -> -0.070231221 | AK12: =IF($G12="","",(1+AE12)^(1/G12)-1) -> 0.070582313 | AL12: =IF($G12="","",(1+AF12)^(1/G12)-1) -> 0.049749153 | AM12: =IF($G12="","",AL12-AK12) -> -0.02083316 | AN12: =IF($G12="","",(1+AH12)^(1/G12)-1) -> 0.0704 | AO12: =IF($G12="","",(1+AI12)^(1/G12)-1) -> 0.0495648 | AP12: =IF($G12="","",AO12-AN12) -> -0.0208352
G13: 4 | H13: =IF(G13="","",SUMIFS(Add_Contributions[[#All],[Amount ($)]],Add_Contributions[[#All],[Year]],G13)) -> 0 | I13: =IF($G13="","",IF($G13=1,(($C$2+$H13)*I$3)*(1+(I$4-I$5)),((I12+($H13*I$3))*(1+(I$4-I$5))))) -> 6530347 | J13: =IF($G13="","",IF($G13=1,(($C$2+$H13)*J$3)*(1+(J$4-J$5)),((J12+($H13*J$3))*(1+(J$4-J$5))))) -> 6081872.1 | K13: =IF($G13="","",IF($G13=1,(($C$2+$H13)*K$3)*(1+(K$4-K$5)),((K12+($H13*K$3))*(1+(K$4-K$5))))) -> 0 | L13: =IF($G13="","",IF($G13=1,(($C$2+$H13)*L$3)*(1+(L$4-L$5)),((L12+($H13*L$3))*(1+(L$4-L$5))))) -> 0 | M13: =IF($G13="","",IF($G13=1,(($C$2+$H13)*M$3)*(1+(M$4-M$5)),((M12+($H13*M$3))*(1+(M$4-M$5))))) -> 3889620 | N13: =IF($G13="","",IF($G13=1,(($C$2+$H13)*N$3)*(1+(N$4-N$5)),((N12+($H13*N$3))*(1+(N$4-N$5))))) -> 3596036.7 | O13: =IF($G13="","",IF($G13=1,(($C$2+$H13)*O$3)*(1+(O$4-O$5)),((O12+($H13*O$3))*(1+(O$4-O$5))))) -> 0 | P13: =IF($G13="","",IF($G13=1,(($C$2+$H13)*P$3)*(1+(P$4-P$5)),((P12+($H13*P$3))*(1+(P$4-P$5))))) -> 0 | ... T13: =IF($G13="","",IF($G13=1,(($C$2+$H13)*T$3)*(1+(T$4-T$5)),((T12+($H13*T$3))*(1+(T$4-T$5))))) -> 0 | U13: =IF(G13="","",SUM(I13,K13,M13,O13,Q13,S13)) -> 13140945 | V13: =IF(H13="","",SUM(J13,L13,N13,P13,R13,T13)) -> 12147677 | W13: =IF($G13="","",IF($G13=1,(($C$2+$H13)*W$3)*(1+(W$4-W$5)),((W12+($H13*W$3))*(1+(W$4-W$5))))) -> 13127572 | X13: =IF($G13="","",IF($G13=1,(($C$2+$H13)*X$3)*(1+(X$4-X$5)),((X12+($H13*X$3))*(1+(X$4-X$5))))) -> 12134923 | Y13: =IF($G13="","",IF($G13=1,(U13-$C$2-H13)/($C$2+H13),(U13-U12-H13)/(U12+H13))) -> 0.070943113 | Z13: =IF($G13="","",IF($G13=1,(V13-$C$2-H13)/($C$2+H13),(V13-V12-H13)/(V12+H13))) -> 0.050114419 | AA13: =IF($G13="","",Z13-Y13) -> -0.020828695 | AB13: =IF($G13="","",IF($G13=1,(W13-$C$2-H13)/($C$2+H13),(W13-W12-H13)/(W12+H13))) -> 0.0704 | AC13: =IF($G13="","",IF($G13=1,(X13-$C$2-H13)/($C$2+H13),(X13-X12-H13)/(X12+H13))) -> 0.0495648 | AD13: =IF($G13="","",AC13-AB13) -> -0.0208352 | AE13: =IF($G13="","",IF($G13=1,Y13,(1+Y13)*(1+AE12)-1)) -> 0.31409449 | AF13: =IF($G13="","",IF($G13=1,Z13,(1+Z13)*(1+AF12)-1)) -> 0.21476766 | AG13: =IF($G13="","",AF13-AE13) -> -0.099326837 | AH13: =IF($G13="","",IF($G13=1,AB13,(1+AB13)*(1+AH12)-1)) -> 0.31275718 | AI13: =IF($G13="","",IF($G13=1,AC13,(1+AC13)*(1+AI12)-1)) -> 0.21349231 | AJ13: =IF($G13="","",AI13-AH13) -> -0.099264869 | AK13: =IF($G13="","",(1+AE13)^(1/G13)-1) -> 0.070672502 | AL13: =IF($G13="","",(1+AF13)^(1/G13)-1) -> 0.049840457 | AM13: =IF($G13="","",AL13-AK13) -> -0.020832044 | AN13: =IF($G13="","",(1+AH13)^(1/G13)-1) -> 0.0704 | AO13: =IF($G13="","",(1+AI13)^(1/G13)-1) -> 0.0495648 | AP13: =IF($G13="","",AO13-AN13) -> -0.0208352
B14: Federal Income Tax | C14: ='Return Simulator'!D61 -> 0.37 | G14: 5 | H14: =IF(G14="","",SUMIFS(Add_Contributions[[#All],[Amount ($)]],Add_Contributions[[#All],[Year]],G14)) -> 0 | I14: =IF($G14="","",IF($G14=1,(($C$2+$H14)*I$3)*(1+(I$4-I$5)),((I13+($H14*I$3))*(1+(I$4-I$5))))) -> 7052774.8 | J14: =IF($G14="","",IF($G14=1,(($C$2+$H14)*J$3)*(1+(J$4-J$5)),((J13+($H14*J$3))*(1+(J$4-J$5))))) -> 6452623 | K14: =IF($G14="","",IF($G14=1,(($C$2+$H14)*K$3)*(1+(K$4-K$5)),((K13+($H14*K$3))*(1+(K$4-K$5))))) -> 0 | L14: =IF($G14="","",IF($G14=1,(($C$2+$H14)*L$3)*(1+(L$4-L$5)),((L13+($H14*L$3))*(1+(L$4-L$5))))) -> 0 | M14: =IF($G14="","",IF($G14=1,(($C$2+$H14)*M$3)*(1+(M$4-M$5)),((M13+($H14*M$3))*(1+(M$4-M$5))))) -> 4084101 | N14: =IF($G14="","",IF($G14=1,(($C$2+$H14)*N$3)*(1+(N$4-N$5)),((N13+($H14*N$3))*(1+(N$4-N$5))))) -> 3702479.4 | O14: =IF($G14="","",IF($G14=1,(($C$2+$H14)*O$3)*(1+(O$4-O$5)),((O13+($H14*O$3))*(1+(O$4-O$5))))) -> 0 | P14: =IF($G14="","",IF($G14=1,(($C$2+$H14)*P$3)*(1+(P$4-P$5)),((P13+($H14*P$3))*(1+(P$4-P$5))))) -> 0 | ... T14: =IF($G14="","",IF($G14=1,(($C$2+$H14)*T$3)*(1+(T$4-T$5)),((T13+($H14*T$3))*(1+(T$4-T$5))))) -> 0 | U14: =IF(G14="","",SUM(I14,K14,M14,O14,Q14,S14)) -> 14075532 | V14: =IF(H14="","",SUM(J14,L14,N14,P14,R14,T14)) -> 12758633 | W14: =IF($G14="","",IF($G14=1,(($C$2+$H14)*W$3)*(1+(W$4-W$5)),((W13+($H14*W$3))*(1+(W$4-W$5))))) -> 14051753 | X14: =IF($G14="","",IF($G14=1,(($C$2+$H14)*X$3)*(1+(X$4-X$5)),((X13+($H14*X$3))*(1+(X$4-X$5))))) -> 12736388 | Y14: =IF($G14="","",IF($G14=1,(U14-$C$2-H14)/($C$2+H14),(U14-U13-H14)/(U13+H14))) -> 0.071120228 | Z14: =IF($G14="","",IF($G14=1,(V14-$C$2-H14)/($C$2+H14),(V14-V13-H14)/(V13+H14))) -> 0.050294081 | AA14: =IF($G14="","",Z14-Y14) -> -0.020826146 | AB14: =IF($G14="","",IF($G14=1,(W14-$C$2-H14)/($C$2+H14),(W14-W13-H14)/(W13+H14))) -> 0.0704 | AC14: =IF($G14="","",IF($G14=1,(X14-$C$2-H14)/($C$2+H14),(X14-X13-H14)/(X13+H14))) -> 0.0495648 | AD14: =IF($G14="","",AC14-AB14) -> -0.0208352 | AE14: =IF($G14="","",IF($G14=1,Y14,(1+Y14)*(1+AE13)-1)) -> 0.40755319 | AF14: =IF($G14="","",IF($G14=1,Z14,(1+Z14)*(1+AF13)-1)) -> 0.27586328 | AG14: =IF($G14="","",AF14-AE14) -> -0.13168991 | AH14: =IF($G14="","",IF($G14=1,AB14,(1+AB14)*(1+AH13)-1)) -> 0.40517528 | AI14: =IF($G14="","",IF($G14=1,AC14,(1+AC14)*(1+AI13)-1)) -> 0.27363881 | AJ14: =IF($G14="","",AI14-AH14) -> -0.13153647 | AK14: =IF($G14="","",(1+AE14)^(1/G14)-1) -> 0.070762032 | AL14: =IF($G14="","",(1+AF14)^(1/G14)-1) -> 0.049931166 | AM14: =IF($G14="","",AL14-AK14) -> -0.020830866 | AN14: =IF($G14="","",(1+AH14)^(1/G14)-1) -> 0.0704 | AO14: =IF($G14="","",(1+AI14)^(1/G14)-1) -> 0.0495648 | AP14: =IF($G14="","",AO14-AN14) -> -0.0208352
B15: Capital Gains Tax | C15: ='Return Simulator'!D62 -> 0.2 | G15: 6 | H15: =IF(G15="","",SUMIFS(Add_Contributions[[#All],[Amount ($)]],Add_Contributions[[#All],[Year]],G15)) -> 0 | I15: =IF($G15="","",IF($G15=1,(($C$2+$H15)*I$3)*(1+(I$4-I$5)),((I14+($H15*I$3))*(1+(I$4-I$5))))) -> 7616996.8 | J15: =IF($G15="","",IF($G15=1,(($C$2+$H15)*J$3)*(1+(J$4-J$5)),((J14+($H15*J$3))*(1+(J$4-J$5))))) -> 6845974.9 | K15: =IF($G15="","",IF($G15=1,(($C$2+$H15)*K$3)*(1+(K$4-K$5)),((K14+($H15*K$3))*(1+(K$4-K$5))))) -> 0 | L15: =IF($G15="","",IF($G15=1,(($C$2+$H15)*L$3)*(1+(L$4-L$5)),((L14+($H15*L$3))*(1+(L$4-L$5))))) -> 0 | M15: =IF($G15="","",IF($G15=1,(($C$2+$H15)*M$3)*(1+(M$4-M$5)),((M14+($H15*M$3))*(1+(M$4-M$5))))) -> 4288306 | N15: =IF($G15="","",IF($G15=1,(($C$2+$H15)*N$3)*(1+(N$4-N$5)),((N14+($H15*N$3))*(1+(N$4-N$5))))) -> 3812072.8 | O15: =IF($G15="","",IF($G15=1,(($C$2+$H15)*O$3)*(1+(O$4-O$5)),((O14+($H15*O$3))*(1+(O$4-O$5))))) -> 0 | P15: =IF($G15="","",IF($G15=1,(($C$2+$H15)*P$3)*(1+(P$4-P$5)),((P14+($H15*P$3))*(1+(P$4-P$5))))) -> 0 | ... T15: =IF($G15="","",IF($G15=1,(($C$2+$H15)*T$3)*(1+(T$4-T$5)),((T14+($H15*T$3))*(1+(T$4-T$5))))) -> 0 | U15: =IF(G15="","",SUM(I15,K15,M15,O15,Q15,S15)) -> 15079051 | V15: =IF(H15="","",SUM(J15,L15,N15,P15,R15,T15)) -> 13402585 | W15: =IF($G15="","",IF($G15=1,(($C$2+$H15)*W$3)*(1+(W$4-W$5)),((W14+($H15*W$3))*(1+(W$4-W$5))))) -> 15040996 | X15: =IF($G15="","",IF($G15=1,(($C$2+$H15)*X$3)*(1+(X$4-X$5)),((X14+($H15*X$3))*(1+(X$4-X$5))))) -> 13367665 | Y15: =IF($G15="","",IF($G15=1,(U15-$C$2-H15)/($C$2+H15),(U15-U14-H15)/(U14+H15))) -> 0.071295318 | Z15: =IF($G15="","",IF($G15=1,(V15-$C$2-H15)/($C$2+H15),(V15-V14-H15)/(V14+H15))) -> 0.050471904 | AA15: =IF($G15="","",Z15-Y15) -> -0.020823414 | AB15: =IF($G15="","",IF($G15=1,(W15-$C$2-H15)/($C$2+H15),(W15-W14-H15)/(W14+H15))) -> 0.0704 | AC15: =IF($G15="","",IF($G15=1,(X15-$C$2-H15)/($C$2+H15),(X15-X14-H15)/(X14+H15))) -> 0.0495648 | AD15: =IF($G15="","",AC15-AB15) -> -0.0208352 | AE15: =IF($G15="","",IF($G15=1,Y15,(1+Y15)*(1+AE14)-1)) -> 0.50790514 | AF15: =IF($G15="","",IF($G15=1,Z15,(1+Z15)*(1+AF14)-1)) -> 0.34025853 | AG15: =IF($G15="","",AF15-AE15) -> -0.16764662 | AH15: =IF($G15="","",IF($G15=1,AB15,(1+AB15)*(1+AH14)-1)) -> 0.50409962 | AI15: =IF($G15="","",IF($G15=1,AC15,(1+AC15)*(1+AI14)-1)) -> 0.33676647 | AJ15: =IF($G15="","",AI15-AH15) -> -0.16733316 | AK15: =IF($G15="","",(1+AE15)^(1/G15)-1) -> 0.070850895 | AL15: =IF($G15="","",(1+AF15)^(1/G15)-1) -> 0.05002127 | AM15: =IF($G15="","",AL15-AK15) -> -0.020829624 | AN15: =IF($G15="","",(1+AH15)^(1/G15)-1) -> 0.0704 | AO15: =IF($G15="","",(1+AI15)^(1/G15)-1) -> 0.0495648 | AP15: =IF($G15="","",AO15-AN15) -> -0.0208352
B16: Net Investment Income Tax | C16: ='Return Simulator'!D63 -> 0.038 | G16: 7 | H16: =IF(G16="","",SUMIFS(Add_Contributions[[#All],[Amount ($)]],Add_Contributions[[#All],[Year]],G16)) -> 0 | I16: =IF($G16="","",IF($G16=1,(($C$2+$H16)*I$3)*(1+(I$4-I$5)),((I15+($H16*I$3))*(1+(I$4-I$5))))) -> 8226356.5 | J16: =IF($G16="","",IF($G16=1,(($C$2+$H16)*J$3)*(1+(J$4-J$5)),((J15+($H16*J$3))*(1+(J$4-J$5))))) -> 7263305.5 | K16: =IF($G16="","",IF($G16=1,(($C$2+$H16)*K$3)*(1+(K$4-K$5)),((K15+($H16*K$3))*(1+(K$4-K$5))))) -> 0 | L16: =IF($G16="","",IF($G16=1,(($C$2+$H16)*L$3)*(1+(L$4-L$5)),((L15+($H16*L$3))*(1+(L$4-L$5))))) -> 0 | M16: =IF($G16="","",IF($G16=1,(($C$2+$H16)*M$3)*(1+(M$4-M$5)),((M15+($H16*M$3))*(1+(M$4-M$5))))) -> 4502721.4 | N16: =IF($G16="","",IF($G16=1,(($C$2+$H16)*N$3)*(1+(N$4-N$5)),((N15+($H16*N$3))*(1+(N$4-N$5))))) -> 3924910.1 | O16: =IF($G16="","",IF($G16=1,(($C$2+$H16)*O$3)*(1+(O$4-O$5)),((O15+($H16*O$3))*(1+(O$4-O$5))))) -> 0 | P16: =IF($G16="","",IF($G16=1,(($C$2+$H16)*P$3)*(1+(P$4-P$5)),((P15+($H16*P$3))*(1+(P$4-P$5))))) -> 0 | ... T16: =IF($G16="","",IF($G16=1,(($C$2+$H16)*T$3)*(1+(T$4-T$5)),((T15+($H16*T$3))*(1+(T$4-T$5))))) -> 0 | U16: =IF(G16="","",SUM(I16,K16,M16,O16,Q16,S16)) -> 16156726 | V16: =IF(H16="","",SUM(J16,L16,N16,P16,R16,T16)) -> 14081397 | W16: =IF($G16="","",IF($G16=1,(($C$2+$H16)*W$3)*(1+(W$4-W$5)),((W15+($H16*W$3))*(1+(W$4-W$5))))) -> 16099882 | X16: =IF($G16="","",IF($G16=1,(($C$2+$H16)*X$3)*(1+(X$4-X$5)),((X15+($H16*X$3))*(1+(X$4-X$5))))) -> 14030230 | Y16: =IF($G16="","",IF($G16=1,(U16-$C$2-H16)/($C$2+H16),(U16-U15-H16)/(U15+H16))) -> 0.071468351 | Z16: =IF($G16="","",IF($G16=1,(V16-$C$2-H16)/($C$2+H16),(V16-V15-H16)/(V15+H16))) -> 0.050647851 | AA16: =IF($G16="","",Z16-Y16) -> -0.0208205 | AB16: =IF($G16="","",IF($G16=1,(W16-$C$2-H16)/($C$2+H16),(W16-W15-H16)/(W15+H16))) -> 0.0704 | AC16: =IF($G16="","",IF($G16=1,(X16-$C$2-H16)/($C$2+H16),(X16-X15-H16)/(X15+H16))) -> 0.0495648 | AD16: =IF($G16="","",AC16-AB16) -> -0.0208352 | AE16: =IF($G16="","",IF($G16=1,Y16,(1+Y16)*(1+AE15)-1)) -> 0.61567264 | AF16: =IF($G16="","",IF($G16=1,Z16,(1+Z16)*(1+AF15)-1)) -> 0.40813974 | AG16: =IF($G16="","",AF16-AE16) -> -0.2075329 | AH16: =IF($G16="","",IF($G16=1,AB16,(1+AB16)*(1+AH15)-1)) -> 0.60998824 | AI16: =IF($G16="","",IF($G16=1,AC16,(1+AC16)*(1+AI15)-1)) -> 0.40302303 | AJ16: =IF($G16="","",AI16-AH16) -> -0.20696521 | AK16: =IF($G16="","",(1+AE16)^(1/G16)-1) -> 0.070939081 | AL16: =IF($G16="","",(1+AF16)^(1/G16)-1) -> 0.050110759 | AM16: =IF($G16="","",AL16-AK16) -> -0.020828322 | AN16: =IF($G16="","",(1+AH16)^(1/G16)-1) -> 0.0704 | AO16: =IF($G16="","",(1+AI16)^(1/G16)-1) -> 0.0495648 | AP16: =IF($G16="","",AO16-AN16) -> -0.0208352
B17: State Income Tax | G17: 8 | H17: =IF(G17="","",SUMIFS(Add_Contributions[[#All],[Amount ($)]],Add_Contributions[[#All],[Year]],G17)) -> 0 | I17: =IF($G17="","",IF($G17=1,(($C$2+$H17)*I$3)*(1+(I$4-I$5)),((I16+($H17*I$3))*(1+(I$4-I$5))))) -> 8884465 | J17: =IF($G17="","",IF($G17=1,(($C$2+$H17)*J$3)*(1+(J$4-J$5)),((J16+($H17*J$3))*(1+(J$4-J$5))))) -> 7706076.6 | K17: =IF($G17="","",IF($G17=1,(($C$2+$H17)*K$3)*(1+(K$4-K$5)),((K16+($H17*K$3))*(1+(K$4-K$5))))) -> 0 | L17: =IF($G17="","",IF($G17=1,(($C$2+$H17)*L$3)*(1+(L$4-L$5)),((L16+($H17*L$3))*(1+(L$4-L$5))))) -> 0 | M17: =IF($G17="","",IF($G17=1,(($C$2+$H17)*M$3)*(1+(M$4-M$5)),((M16+($H17*M$3))*(1+(M$4-M$5))))) -> 4727857.4 | N17: =IF($G17="","",IF($G17=1,(($C$2+$H17)*N$3)*(1+(N$4-N$5)),((N16+($H17*N$3))*(1+(N$4-N$5))))) -> 4041087.5 | O17: =IF($G17="","",IF($G17=1,(($C$2+$H17)*O$3)*(1+(O$4-O$5)),((O16+($H17*O$3))*(1+(O$4-O$5))))) -> 0 | P17: =IF($G17="","",IF($G17=1,(($C$2+$H17)*P$3)*(1+(P$4-P$5)),((P16+($H17*P$3))*(1+(P$4-P$5))))) -> 0 | ... T17: =IF($G17="","",IF($G17=1,(($C$2+$H17)*T$3)*(1+(T$4-T$5)),((T16+($H17*T$3))*(1+(T$4-T$5))))) -> 0 | U17: =IF(G17="","",SUM(I17,K17,M17,O17,Q17,S17)) -> 17314183 | V17: =IF(H17="","",SUM(J17,L17,N17,P17,R17,T17)) -> 14797041 | W17: =IF($G17="","",IF($G17=1,(($C$2+$H17)*W$3)*(1+(W$4-W$5)),((W16+($H17*W$3))*(1+(W$4-W$5))))) -> 17233314 | X17: =IF($G17="","",IF($G17=1,(($C$2+$H17)*X$3)*(1+(X$4-X$5)),((X16+($H17*X$3))*(1+(X$4-X$5))))) -> 14725636 | Y17: =IF($G17="","",IF($G17=1,(U17-$C$2-H17)/($C$2+H17),(U17-U16-H17)/(U16+H17))) -> 0.071639294 | Z17: =IF($G17="","",IF($G17=1,(V17-$C$2-H17)/($C$2+H17),(V17-V16-H17)/(V16+H17))) -> 0.050821886 | AA17: =IF($G17="","",Z17-Y17) -> -0.020817408 | AB17: =IF($G17="","",IF($G17=1,(W17-$C$2-H17)/($C$2+H17),(W17-W16-H17)/(W16+H17))) -> 0.0704 | AC17: =IF($G17="","",IF($G17=1,(X17-$C$2-H17)/($C$2+H17),(X17-X16-H17)/(X16+H17))) -> 0.0495648 | AD17: =IF($G17="","",AC17-AB17) -> -0.0208352 | AE17: =IF($G17="","",IF($G17=1,Y17,(1+Y17)*(1+AE16)-1)) -> 0.73141829 | AF17: =IF($G17="","",IF($G17=1,Z17,(1+Z17)*(1+AF16)-1)) -> 0.47970406 | AG17: =IF($G17="","",AF17-AE17) -> -0.25171423 | AH17: =IF($G17="","",IF($G17=1,AB17,(1+AB17)*(1+AH16)-1)) -> 0.72333141 | AI17: =IF($G17="","",IF($G17=1,AC17,(1+AC17)*(1+AI16)-1)) -> 0.47256358 | AJ17: =IF($G17="","",AI17-AH17) -> -0.25076783 | AK17: =IF($G17="","",(1+AE17)^(1/G17)-1) -> 0.071026582 | AL17: =IF($G17="","",(1+AF17)^(1/G17)-1) -> 0.050199623 | AM17: =IF($G17="","",AL17-AK17) -> -0.020826959 | AN17: =IF($G17="","",(1+AH17)^(1/G17)-1) -> 0.0704 | AO17: =IF($G17="","",(1+AI17)^(1/G17)-1) -> 0.0495648 | AP17: =IF($G17="","",AO17-AN17) -> -0.0208352
G18: 9 | H18: =IF(G18="","",SUMIFS(Add_Contributions[[#All],[Amount ($)]],Add_Contributions[[#All],[Year]],G18)) -> 0 | I18: =IF($G18="","",IF($G18=1,(($C$2+$H18)*I$3)*(1+(I$4-I$5)),((I17+($H18*I$3))*(1+(I$4-I$5))))) -> 9595222.2 | J18: =IF($G18="","",IF($G18=1,(($C$2+$H18)*J$3)*(1+(J$4-J$5)),((J17+($H18*J$3))*(1+(J$4-J$5))))) -> 8175839 | K18: =IF($G18="","",IF($G18=1,(($C$2+$H18)*K$3)*(1+(K$4-K$5)),((K17+($H18*K$3))*(1+(K$4-K$5))))) -> 0 | L18: =IF($G18="","",IF($G18=1,(($C$2+$H18)*L$3)*(1+(L$4-L$5)),((L17+($H18*L$3))*(1+(L$4-L$5))))) -> 0 | M18: =IF($G18="","",IF($G18=1,(($C$2+$H18)*M$3)*(1+(M$4-M$5)),((M17+($H18*M$3))*(1+(M$4-M$5))))) -> 4964250.3 | N18: =IF($G18="","",IF($G18=1,(($C$2+$H18)*N$3)*(1+(N$4-N$5)),((N17+($H18*N$3))*(1+(N$4-N$5))))) -> 4160703.6 | O18: =IF($G18="","",IF($G18=1,(($C$2+$H18)*O$3)*(1+(O$4-O$5)),((O17+($H18*O$3))*(1+(O$4-O$5))))) -> 0 | P18: =IF($G18="","",IF($G18=1,(($C$2+$H18)*P$3)*(1+(P$4-P$5)),((P17+($H18*P$3))*(1+(P$4-P$5))))) -> 0 | ... T18: =IF($G18="","",IF($G18=1,(($C$2+$H18)*T$3)*(1+(T$4-T$5)),((T17+($H18*T$3))*(1+(T$4-T$5))))) -> 0 | U18: =IF(G18="","",SUM(I18,K18,M18,O18,Q18,S18)) -> 18557482 | V18: =IF(H18="","",SUM(J18,L18,N18,P18,R18,T18)) -> 15551601 | W18: =IF($G18="","",IF($G18=1,(($C$2+$H18)*W$3)*(1+(W$4-W$5)),((W17+($H18*W$3))*(1+(W$4-W$5))))) -> 18446539 | X18: =IF($G18="","",IF($G18=1,(($C$2+$H18)*X$3)*(1+(X$4-X$5)),((X17+($H18*X$3))*(1+(X$4-X$5))))) -> 15455509 | Y18: =IF($G18="","",IF($G18=1,(U18-$C$2-H18)/($C$2+H18),(U18-U17-H18)/(U17+H18))) -> 0.071808119 | Z18: =IF($G18="","",IF($G18=1,(V18-$C$2-H18)/($C$2+H18),(V18-V17-H18)/(V17+H18))) -> 0.050993976 | AA18: =IF($G18="","",Z18-Y18) -> -0.020814143 | AB18: =IF($G18="","",IF($G18=1,(W18-$C$2-H18)/($C$2+H18),(W18-W17-H18)/(W17+H18))) -> 0.0704 | AC18: =IF($G18="","",IF($G18=1,(X18-$C$2-H18)/($C$2+H18),(X18-X17-H18)/(X17+H18))) -> 0.0495648 | AD18: =IF($G18="","",AC18-AB18) -> -0.0208352 | AE18: =IF($G18="","",IF($G18=1,Y18,(1+Y18)*(1+AE17)-1)) -> 0.85574818 | AF18: =IF($G18="","",IF($G18=1,Z18,(1+Z18)*(1+AF17)-1)) -> 0.55516005 | AG18: =IF($G18="","",AF18-AE18) -> -0.30058812 | AH18: =IF($G18="","",IF($G18=1,AB18,(1+AB18)*(1+AH17)-1)) -> 0.84465394 | AI18: =IF($G18="","",IF($G18=1,AC18,(1+AC18)*(1+AI17)-1)) -> 0.5455509 | AJ18: =IF($G18="","",AI18-AH18) -> -0.29910304 | AK18: =IF($G18="","",(1+AE18)^(1/G18)-1) -> 0.071113392 | AL18: =IF($G18="","",(1+AF18)^(1/G18)-1) -> 0.050287855 | AM18: =IF($G18="","",AL18-AK18) -> -0.020825537 | AN18: =IF($G18="","",(1+AH18)^(1/G18)-1) -> 0.0704 | AO18: =IF($G18="","",(1+AI18)^(1/G18)-1) -> 0.0495648 | AP18: =IF($G18="","",AO18-AN18) -> -0.0208352
G19: 10 | H19: =IF(G19="","",SUMIFS(Add_Contributions[[#All],[Amount ($)]],Add_Contributions[[#All],[Year]],G19)) -> 0 | I19: =IF($G19="","",IF($G19=1,(($C$2+$H19)*I$3)*(1+(I$4-I$5)),((I18+($H19*I$3))*(1+(I$4-I$5))))) -> 10362840 | J19: =IF($G19="","",IF($G19=1,(($C$2+$H19)*J$3)*(1+(J$4-J$5)),((J18+($H19*J$3))*(1+(J$4-J$5))))) -> 8674238.2 | K19: =IF($G19="","",IF($G19=1,(($C$2+$H19)*K$3)*(1+(K$4-K$5)),((K18+($H19*K$3))*(1+(K$4-K$5))))) -> 0 | L19: =IF($G19="","",IF($G19=1,(($C$2+$H19)*L$3)*(1+(L$4-L$5)),((L18+($H19*L$3))*(1+(L$4-L$5))))) -> 0 | M19: =IF($G19="","",IF($G19=1,(($C$2+$H19)*M$3)*(1+(M$4-M$5)),((M18+($H19*M$3))*(1+(M$4-M$5))))) -> 5212462.8 | N19: =IF($G19="","",IF($G19=1,(($C$2+$H19)*N$3)*(1+(N$4-N$5)),((N18+($H19*N$3))*(1+(N$4-N$5))))) -> 4283860.5 | O19: =IF($G19="","",IF($G19=1,(($C$2+$H19)*O$3)*(1+(O$4-O$5)),((O18+($H19*O$3))*(1+(O$4-O$5))))) -> 0 | P19: =IF($G19="","",IF($G19=1,(($C$2+$H19)*P$3)*(1+(P$4-P$5)),((P18+($H19*P$3))*(1+(P$4-P$5))))) -> 0 | ... T19: =IF($G19="","",IF($G19=1,(($C$2+$H19)*T$3)*(1+(T$4-T$5)),((T18+($H19*T$3))*(1+(T$4-T$5))))) -> 0 | U19: =IF(G19="","",SUM(I19,K19,M19,O19,Q19,S19)) -> 19893153 | V19: =IF(H19="","",SUM(J19,L19,N19,P19,R19,T19)) -> 16347284 | W19: =IF($G19="","",IF($G19=1,(($C$2+$H19)*W$3)*(1+(W$4-W$5)),((W18+($H19*W$3))*(1+(W$4-W$5))))) -> 19745176 | X19: =IF($G19="","",IF($G19=1,(($C$2+$H19)*X$3)*(1+(X$4-X$5)),((X18+($H19*X$3))*(1+(X$4-X$5))))) -> 16221558 | Y19: =IF($G19="","",IF($G19=1,(U19-$C$2-H19)/($C$2+H19),(U19-U18-H19)/(U18+H19))) -> 0.0719748 | Z19: =IF($G19="","",IF($G19=1,(V19-$C$2-H19)/($C$2+H19),(V19-V18-H19)/(V18+H19))) -> 0.051164091 | AA19: =IF($G19="","",Z19-Y19) -> -0.020810708 | AB19: =IF($G19="","",IF($G19=1,(W19-$C$2-H19)/($C$2+H19),(W19-W18-H19)/(W18+H19))) -> 0.0704 | AC19: =IF($G19="","",IF($G19=1,(X19-$C$2-H19)/($C$2+H19),(X19-X18-H19)/(X18+H19))) -> 0.0495648 | AD19: =IF($G19="","",AC19-AB19) -> -0.0208352 | AE19: =IF($G19="","",IF($G19=1,Y19,(1+Y19)*(1+AE18)-1)) -> 0.98931528 | AF19: =IF($G19="","",IF($G19=1,Z19,(1+Z19)*(1+AF18)-1)) -> 0.6347284 | AG19: =IF($G19="","",AF19-AE19) -> -0.35458687 | AH19: =IF($G19="","",IF($G19=1,AB19,(1+AB19)*(1+AH18)-1)) -> 0.97451758 | AI19: =IF($G19="","",IF($G19=1,AC19,(1+AC19)*(1+AI18)-1)) -> 0.62215582 | AJ19: =IF($G19="","",AI19-AH19) -> -0.35236175 | AK19: =IF($G19="","",(1+AE19)^(1/G19)-1) -> 0.071199501 | AL19: =IF($G19="","",(1+AF19)^(1/G19)-1) -> 0.050375446 | AM19: =IF($G19="","",AL19-AK19) -> -0.020824056 | AN19: =IF($G19="","",(1+AH19)^(1/G19)-1) -> 0.0704 | AO19: =IF($G19="","",(1+AI19)^(1/G19)-1) -> 0.0495648 | AP19: =IF($G19="","",AO19-AN19) -> -0.0208352
